Workbook
Name DESCRIPTORS: 'Helper (Do Not Delete)'!$T$3:$W$7
Name FemaleLearners: INPUT!$B$63:$B$112
Name MaleLearners: INPUT!$B$12:$B$61
Name NewTransmu: 'Helper (Do Not Delete)'!$H$3:$K$43
Name T1_Names: TERM1!$B$12:$B$112
Name TRANSMUTATION_TABLE: 'DO NOT DELETE'!$G$2:$J$42

Sheet INPUT
A1: Class Record
A3: (Waiting for the Official DepEd Order)
B4: REGION | I4: DIVISION
B5: SCHOOL NAME | Q5: SCHOOL ID | V5: SCHOOL YEAR
F7: GRADE & SECTION: | N7: TEACHER: | W7: SUBJECT: | Y7: Science
B8: LEARNERS' NAMES
B10: HIGHEST POSSIBLE SCORE
B11: MALE
A12: 1 | B12: Alvarez, Neitan | AS12: =(V12/$V$10)*100 -> #DIV/0!
A13: 2 | B13: Bautista, Mark | AS13: =(V13/$V$10)*100 -> #DIV/0!
A14: 3 | B14: Castro, Daniel | AS14: =(V14/$V$10)*100 -> #DIV/0!
A15: 4 | AS15: =(V15/$V$10)*100 -> #DIV/0!
A16: 5 | AS16: =(V16/$V$10)*100 -> #DIV/0!
A17: 6 | AS17: =(V17/$V$10)*100 -> #DIV/0!
A18: 7 | AS18: =(V18/$V$10)*100 -> #DIV/0!
A19: 8 | AS19: =(V19/$V$10)*100 -> #DIV/0!
A20: 9 | AS20: =(V20/$V$10)*100 -> #DIV/0!
A21: 10 | AS21: =(V21/$V$10)*100 -> #DIV/0!
A22: 11 | AS22: =(V22/$V$10)*100 -> #DIV/0!
A23: 12 | AS23: =(V23/$V$10)*100 -> #DIV/0!
A24: 13 | AS24: =(V24/$V$10)*100 -> #DIV/0!
A25: 14 | AS25: =(V25/$V$10)*100 -> #DIV/0!
A26: 15 | AS26: =(V26/$V$10)*100 -> #DIV/0!
... A61: 50 | AS61: =(V61/$V$10)*100 -> #DIV/0!
B62: FEMALE | AS62: =(V62/$V$10)*100 -> #DIV/0!
A63: 1 | B63: Alcantara, Angela | AS63: =(V63/$V$10)*100 -> #DIV/0!
A64: 2 | B64: Bonifacio, Bea | AS64: =(V64/$V$10)*100 -> #DIV/0!
A65: 3 | B65: Cruz, Claire | AS65: =(V65/$V$10)*100 -> #DIV/0!
A66: 4 | AS66: =(V66/$V$10)*100 -> #DIV/0!
A67: 5 | AS67: =(V67/$V$10)*100 -> #DIV/0!
A68: 6 | AS68: =(V68/$V$10)*100 -> #DIV/0!
A69: 7 | AS69: =(V69/$V$10)*100 -> #DIV/0!
A70: 8 | AS70: =(V70/$V$10)*100 -> #DIV/0!
A71: 9 | AS71: =(V71/$V$10)*100 -> #DIV/0!
A72: 10 | AS72: =(V72/$V$10)*100 -> #DIV/0!
A73: 11 | AS73: =(V73/$V$10)*100 -> #DIV/0!
A74: 12 | AS74: =(V74/$V$10)*100 -> #DIV/0!
A75: 13 | AS75: =(V75/$V$10)*100 -> #DIV/0!
A76: 14 | AS76: =(V76/$V$10)*100 -> #DIV/0!
A77: 15 | AS77: =(V77/$V$10)*100 -> #DIV/0!
...

Sheet TERM1
A1: Class Record
B4: REGION | G4: =INPUT!G4 -> 0 | I4: DIVISION | L4: =INPUT!L4 -> 0
B5: SCHOOL NAME | G5: =INPUT!G5 -> 0 | Q5: SCHOOL ID | S5: =INPUT!S5 -> 0 | V5: SCHOOL YEAR | Z5: =INPUT!Y5 -> 0
A7: TERM 1 | F7: GRADE & SECTION: | J7: =INPUT!J7 -> 0 | N7: TEACHER: | Q7: =INPUT!Q7 -> 0 | X7: SUBJECT: | Z7: =INPUT!Y7 -> Science
B8: LEARNERS' NAMES | F8: WRITTEN / ORAL WORKS (20%) | N8: PRODUCT / PERFORMANCE TASKS (50%) | T8: SUMMATIVE TESTS AND TERM EXAMINATIONS (30%) | Z8: Initial Grade | AA8: TERM GRADE | AB8: DESCRIPTOR
F9: 1 | G9: 2 | H9: 3 | I9: 4 | J9: 5 | K9: Total | L9: PS | M9: WS | N9: 1 | O9: 2 | P9: 3 | Q9: Total | R9: PS | S9: WS | T9: ST1 | U9: ST2 | V9: TE | W9: Total | X9: PS | Y9: WS
B10: HIGHEST POSSIBLE SCORE | F10: 10 | G10: 15 | H10: 15 | I10: 10 | J10: 15 | K10: =IF(COUNT($F10:$J10)=0,"",SUM($F10:$J10)) -> 65 | L10: 100 | M10: 0.2 | N10: 100 | O10: 100 | P10: 100 | Q10: =IF(COUNT($N10:$P10)=0,"",SUM($N10:$P10)) -> 300 | R10: 100 | S10: 0.5 | T10: 50 | U10: 50 | V10: 50 | W10: {=IF(COUNT($T10:$V10=0),"",SUM($T10:$V10))} -> 150 | X10: 100 | Y10: 0.3
B11: MALE | AD11: TEST/EXAM RESULT ANALYSIS | AV11: ST1 | AW11: ST2 | AX11: TE
A12: 1 | B12: =INPUT!B12 -> Alvarez, Neitan | F12: 3 | G12: 5 | H12: 7 | I12: 8 | J12: 9 | K12: =IF(COUNT($F12:$J12)=0,"",SUM($F12:$J12)) -> 32 | L12: =IF(ISERROR(IF($K12="","",ROUND(($K12/$K$10)*$L$10,2))),"",IF($K12="","",ROUND(($K12/$K$10)*$L$10,2))) -> 49.23 | M12: =IF($L12="","",ROUND($L12*$M$10,2)) -> 9.85 | N12: 60 | O12: 65 | P12: 50 | Q12: =IF(COUNT($N12:$P12)=0,"",SUM($N12:$P12)) -> 175 | R12: =IF(ISERROR(IF($Q12="","",ROUND(($Q12/$Q$10)*$R$10,2))),"",IF($Q12="","",ROUND(($Q12/$Q$10)*$R$10,2))) -> 58.33 | S12: =IF($R12="","",ROUND($R12*$S$10,2)) -> 29.17 | T12: 43 | U12: 42 | V12: 40 | W12: =IF(COUNT($T12:$V12)=0,"",SUM($T12:$V12)) -> 125 | X12: =IF(ISERROR(IF($W12="","",ROUND(($W12/$W$10)*$X$10,2))),"",IF($W12="","",ROUND(($W12/$W$10)*$X$10,2))) -> 83.33 | Y12: =IF($X12="","",ROUND($X12*$Y$10,2)) -> 25 | Z12: =IF(ISERROR(IF($W12="","",ROUND(SUM($M12,$S12,$Y12),2))),"",IF($W12="","",ROUND(SUM($M12,$S12,$Y12),2))) -> 64.02 | AA12: =IF(ISERROR(IF($W12="","",VLOOKUP(Z12,NewTransmu,4,TRUE))),"",IF($W12="","",VLOOKUP(Z12,NewTransmu,4,TRUE))) -> 72 | AB12: =IF(ISERROR(IF(AA12="","",VLOOKUP(AA12,DESCRIPTORS,4,TRUE))),"",IF(AA12="","",VLOOKUP(AA12,DESCRIPTORS,4,TRUE))) -> Developing | AV12: =(T12/$T$10)*100 -> 86 | AW12: =(U12/$U$10)*100 -> 84 | AX12: =(V12/$V$10)*100 -> 80
A13: 2 | B13: =INPUT!B13 -> Bautista, Mark | F13: 8 | G13: 13 | H13: 12 | I13: 7 | J13: 14 | K13: =IF(COUNT($F13:$J13)=0,"",SUM($F13:$J13)) -> 54 | L13: =IF(ISERROR(IF($K13="","",ROUND(($K13/$K$10)*$L$10,2))),"",IF($K13="","",ROUND(($K13/$K$10)*$L$10,2))) -> 83.08 | M13: =IF($L13="","",ROUND($L13*$M$10,2)) -> 16.62 | N13: 95 | O13: 90 | P13: 91 | Q13: =IF(COUNT($N13:$P13)=0,"",SUM($N13:$P13)) -> 276 | R13: =IF(ISERROR(IF($Q13="","",ROUND(($Q13/$Q$10)*$R$10,2))),"",IF($Q13="","",ROUND(($Q13/$Q$10)*$R$10,2))) -> 92 | S13: =IF($R13="","",ROUND($R13*$S$10,2)) -> 46 | T13: 40 | U13: 41 | V13: 45 | W13: =IF(COUNT($T13:$V13)=0,"",SUM($T13:$V13)) -> 126 | X13: =IF(ISERROR(IF($W13="","",ROUND(($W13/$W$10)*$X$10,2))),"",IF($W13="","",ROUND(($W13/$W$10)*$X$10,2))) -> 84 | Y13: =IF($X13="","",ROUND($X13*$Y$10,2)) -> 25.2 | Z13: =IF(ISERROR(IF($V13="","",ROUND(SUM($M13,$S13,$Y13),2))),"",IF($V13="","",ROUND(SUM($M13,$S13,$Y13),2))) -> 87.82 | AA13: =IF(ISERROR(IF($V13="","",VLOOKUP(Z13,NewTransmu,4,TRUE))),"",IF($V13="","",VLOOKUP(Z13,NewTransmu,4,TRUE))) -> 89 | AB13: =IF(ISERROR(IF(AA13="","",VLOOKUP(AA13,DESCRIPTORS,4,TRUE))),"",IF(AA13="","",VLOOKUP(AA13,DESCRIPTORS,4,TRUE))) -> Benchmarking | AE13: ST1 | AF13: ST2 | AG13: TE | AV13: =(T13/$T$10)*100 -> 80 | AW13: =(U13/$U$10)*100 -> 82 | AX13: =(V13/$V$10)*100 -> 90
A14: 3 | B14: =INPUT!B14 -> Castro, Daniel | F14: 10 | G14: 13 | H14: 12 | I14: 7 | J14: 14 | K14: =IF(COUNT($F14:$J14)=0,"",SUM($F14:$J14)) -> 56 | L14: =IF(ISERROR(IF($K14="","",ROUND(($K14/$K$10)*$L$10,2))),"",IF($K14="","",ROUND(($K14/$K$10)*$L$10,2))) -> 86.15 | M14: =IF($L14="","",ROUND($L14*$M$10,2)) -> 17.23 | N14: 95 | O14: 90 | P14: 91 | Q14: =IF(COUNT($N14:$P14)=0,"",SUM($N14:$P14)) -> 276 | R14: =IF(ISERROR(IF($Q14="","",ROUND(($Q14/$Q$10)*$R$10,2))),"",IF($Q14="","",ROUND(($Q14/$Q$10)*$R$10,2))) -> 92 | S14: =IF($R14="","",ROUND($R14*$S$10,2)) -> 46 | T14: 45 | U14: 39 | V14: 44 | W14: =IF(COUNT($T14:$V14)=0,"",SUM($T14:$V14)) -> 128 | X14: =IF(ISERROR(IF($W14="","",ROUND(($W14/$W$10)*$X$10,2))),"",IF($W14="","",ROUND(($W14/$W$10)*$X$10,2))) -> 85.33 | Y14: =IF($X14="","",ROUND($X14*$Y$10,2)) -> 25.6 | Z14: =IF(ISERROR(IF($V14="","",ROUND(SUM($M14,$S14,$Y14),2))),"",IF($V14="","",ROUND(SUM($M14,$S14,$Y14),2))) -> 88.83 | AA14: =IF(ISERROR(IF($V14="","",VLOOKUP(Z14,NewTransmu,4,TRUE))),"",IF($V14="","",VLOOKUP(Z14,NewTransmu,4,TRUE))) -> 90 | AB14: =IF(ISERROR(IF(AA14="","",VLOOKUP(AA14,DESCRIPTORS,4,TRUE))),"",IF(AA14="","",VLOOKUP(AA14,DESCRIPTORS,4,TRUE))) -> Advancing | AD14: Number of Examinees: | AE14: =COUNTA(T12:T112) -> 6 | AF14: =COUNTA(U12:U112) -> 6 | AG14: =COUNTA(V12:V112) -> 6 | AV14: =(T14/$T$10)*100 -> 90 | AW14: =(U14/$U$10)*100 -> 78 | AX14: =(V14/$V$10)*100 -> 88
A15: 4 | B15: =INPUT!B15 -> 0 | K15: =IF(COUNT($F15:$J15)=0,"",SUM($F15:$J15)) | L15: =IF(ISERROR(IF($K15="","",ROUND(($K15/$K$10)*$L$10,2))),"",IF($K15="","",ROUND(($K15/$K$10)*$L$10,2))) | M15: =IF($L15="","",ROUND($L15*$M$10,2)) | Q15: =IF(COUNT($N15:$P15)=0,"",SUM($N15:$P15)) | R15: =IF(ISERROR(IF($Q15="","",ROUND(($Q15/$Q$10)*$R$10,2))),"",IF($Q15="","",ROUND(($Q15/$Q$10)*$R$10,2))) | S15: =IF($R15="","",ROUND($R15*$S$10,2)) | W15: =IF(COUNT($T15:$V15)=0,"",SUM($T15:$V15)) | X15: =IF(ISERROR(IF($W15="","",ROUND(($W15/$W$10)*$X$10,2))),"",IF($W15="","",ROUND(($W15/$W$10)*$X$10,2))) | Y15: =IF($X15="","",ROUND($X15*$Y$10,2)) | Z15: =IF(ISERROR(IF($V15="","",ROUND(SUM($M15,$S15,$Y15),2))),"",IF($V15="","",ROUND(SUM($M15,$S15,$Y15),2))) | AA15: =IF(ISERROR(IF($V15="","",VLOOKUP(Z15,NewTransmu,4,TRUE))),"",IF($V15="","",VLOOKUP(Z15,NewTransmu,4,TRUE))) | AB15: =IF(ISERROR(IF(AA15="","",VLOOKUP(AA15,DESCRIPTORS,4,TRUE))),"",IF(AA15="","",VLOOKUP(AA15,DESCRIPTORS,4,TRUE))) | AD15: Highest Possible Score: | AE15: =T10 -> 50 | AF15: =U10 -> 50 | AG15: =V10 -> 50 | AV15: =(T15/$T$10)*100 -> 0 | AW15: =(U15/$U$10)*100 -> 0 | AX15: =(V15/$V$10)*100 -> 0
A16: 5 | B16: =INPUT!B16 -> 0 | K16: =IF(COUNT($F16:$J16)=0,"",SUM($F16:$J16)) | L16: =IF(ISERROR(IF($K16="","",ROUND(($K16/$K$10)*$L$10,2))),"",IF($K16="","",ROUND(($K16/$K$10)*$L$10,2))) | M16: =IF($L16="","",ROUND($L16*$M$10,2)) | Q16: =IF(COUNT($N16:$P16)=0,"",SUM($N16:$P16)) | R16: =IF(ISERROR(IF($Q16="","",ROUND(($Q16/$Q$10)*$R$10,2))),"",IF($Q16="","",ROUND(($Q16/$Q$10)*$R$10,2))) | S16: =IF($R16="","",ROUND($R16*$S$10,2)) | W16: =IF(COUNT($T16:$V16)=0,"",SUM($T16:$V16)) | X16: =IF(ISERROR(IF($W16="","",ROUND(($W16/$W$10)*$X$10,2))),"",IF($W16="","",ROUND(($W16/$W$10)*$X$10,2))) | Y16: =IF($X16="","",ROUND($X16*$Y$10,2)) | Z16: =IF(ISERROR(IF($V16="","",ROUND(SUM($M16,$S16,$Y16),2))),"",IF($V16="","",ROUND(SUM($M16,$S16,$Y16),2))) | AA16: =IF(ISERROR(IF($V16="","",VLOOKUP(Z16,NewTransmu,4,TRUE))),"",IF($V16="","",VLOOKUP(Z16,NewTransmu,4,TRUE))) | AB16: =IF(ISERROR(IF(AA16="","",VLOOKUP(AA16,DESCRIPTORS,4,TRUE))),"",IF(AA16="","",VLOOKUP(AA16,DESCRIPTORS,4,TRUE))) | AV16: =(T16/$T$10)*100 -> 0 | AW16: =(U16/$U$10)*100 -> 0 | AX16: =(V16/$V$10)*100 -> 0
A17: 6 | B17: =INPUT!B17 -> 0 | K17: =IF(COUNT($F17:$J17)=0,"",SUM($F17:$J17)) | L17: =IF(ISERROR(IF($K17="","",ROUND(($K17/$K$10)*$L$10,2))),"",IF($K17="","",ROUND(($K17/$K$10)*$L$10,2))) | M17: =IF($L17="","",ROUND($L17*$M$10,2)) | Q17: =IF(COUNT($N17:$P17)=0,"",SUM($N17:$P17)) | R17: =IF(ISERROR(IF($Q17="","",ROUND(($Q17/$Q$10)*$R$10,2))),"",IF($Q17="","",ROUND(($Q17/$Q$10)*$R$10,2))) | S17: =IF($R17="","",ROUND($R17*$S$10,2)) | W17: =IF(COUNT($T17:$V17)=0,"",SUM($T17:$V17)) | X17: =IF(ISERROR(IF($W17="","",ROUND(($W17/$W$10)*$X$10,2))),"",IF($W17="","",ROUND(($W17/$W$10)*$X$10,2))) | Y17: =IF($X17="","",ROUND($X17*$Y$10,2)) | Z17: =IF(ISERROR(IF($V17="","",ROUND(SUM($M17,$S17,$Y17),2))),"",IF($V17="","",ROUND(SUM($M17,$S17,$Y17),2))) | AA17: =IF(ISERROR(IF($V17="","",VLOOKUP(Z17,NewTransmu,4,TRUE))),"",IF($V17="","",VLOOKUP(Z17,NewTransmu,4,TRUE))) | AB17: =IF(ISERROR(IF(AA17="","",VLOOKUP(AA17,DESCRIPTORS,4,TRUE))),"",IF(AA17="","",VLOOKUP(AA17,DESCRIPTORS,4,TRUE))) | AD17: CRITERION-REFERENCED | AE17: ST1 | AF17: ST2 | AG17: TE | AV17: =(T17/$T$10)*100 -> 0 | AW17: =(U17/$U$10)*100 -> 0 | AX17: =(V17/$V$10)*100 -> 0
A18: 7 | B18: =INPUT!B18 -> 0 | K18: =IF(COUNT($F18:$J18)=0,"",SUM($F18:$J18)) | L18: =IF(ISERROR(IF($K18="","",ROUND(($K18/$K$10)*$L$10,2))),"",IF($K18="","",ROUND(($K18/$K$10)*$L$10,2))) | M18: =IF($L18="","",ROUND($L18*$M$10,2)) | Q18: =IF(COUNT($N18:$P18)=0,"",SUM($N18:$P18)) | R18: =IF(ISERROR(IF($Q18="","",ROUND(($Q18/$Q$10)*$R$10,2))),"",IF($Q18="","",ROUND(($Q18/$Q$10)*$R$10,2))) | S18: =IF($R18="","",ROUND($R18*$S$10,2)) | W18: =IF(COUNT($T18:$V18)=0,"",SUM($T18:$V18)) | X18: =IF(ISERROR(IF($W18="","",ROUND(($W18/$W$10)*$X$10,2))),"",IF($W18="","",ROUND(($W18/$W$10)*$X$10,2))) | Y18: =IF($X18="","",ROUND($X18*$Y$10,2)) | Z18: =IF(ISERROR(IF($V18="","",ROUND(SUM($M18,$S18,$Y18),2))),"",IF($V18="","",ROUND(SUM($M18,$S18,$Y18),2))) | AA18: =IF(ISERROR(IF($V18="","",VLOOKUP(Z18,NewTransmu,4,TRUE))),"",IF($V18="","",VLOOKUP(Z18,NewTransmu,4,TRUE))) | AB18: =IF(ISERROR(IF(AA18="","",VLOOKUP(AA18,DESCRIPTORS,4,TRUE))),"",IF(AA18="","",VLOOKUP(AA18,DESCRIPTORS,4,TRUE))) | AD18: Got 75% & above | AE18: =COUNTIF(AV12:AV112,">=75") -> 4 | AF18: =COUNTIF(AW12:AW112,">=75") -> 5 | AG18: =COUNTIF(AX12:AX112,">=75") -> 5 | AV18: =(T18/$T$10)*100 -> 0 | AW18: =(U18/$U$10)*100 -> 0 | AX18: =(V18/$V$10)*100 -> 0
A19: 8 | B19: =INPUT!B19 -> 0 | K19: =IF(COUNT($F19:$J19)=0,"",SUM($F19:$J19)) | L19: =IF(ISERROR(IF($K19="","",ROUND(($K19/$K$10)*$L$10,2))),"",IF($K19="","",ROUND(($K19/$K$10)*$L$10,2))) | M19: =IF($L19="","",ROUND($L19*$M$10,2)) | Q19: =IF(COUNT($N19:$P19)=0,"",SUM($N19:$P19)) | R19: =IF(ISERROR(IF($Q19="","",ROUND(($Q19/$Q$10)*$R$10,2))),"",IF($Q19="","",ROUND(($Q19/$Q$10)*$R$10,2))) | S19: =IF($R19="","",ROUND($R19*$S$10,2)) | W19: =IF(COUNT($T19:$V19)=0,"",SUM($T19:$V19)) | X19: =IF(ISERROR(IF($W19="","",ROUND(($W19/$W$10)*$X$10,2))),"",IF($W19="","",ROUND(($W19/$W$10)*$X$10,2))) | Y19: =IF($X19="","",ROUND($X19*$Y$10,2)) | Z19: =IF(ISERROR(IF($V19="","",ROUND(SUM($M19,$S19,$Y19),2))),"",IF($V19="","",ROUND(SUM($M19,$S19,$Y19),2))) | AA19: =IF(ISERROR(IF($V19="","",VLOOKUP(Z19,NewTransmu,4,TRUE))),"",IF($V19="","",VLOOKUP(Z19,NewTransmu,4,TRUE))) | AB19: =IF(ISERROR(IF(AA19="","",VLOOKUP(AA19,DESCRIPTORS,4,TRUE))),"",IF(AA19="","",VLOOKUP(AA19,DESCRIPTORS,4,TRUE))) | AD19: Percentage | AE19: =IFERROR(AE18/AE14,"") -> 0.66666667 | AF19: =IFERROR(AF18/AF14,"") -> 0.83333333 | AG19: =IFERROR(AG18/AG14,"") -> 0.83333333 | AV19: =(T19/$T$10)*100 -> 0 | AW19: =(U19/$U$10)*100 -> 0 | AX19: =(V19/$V$10)*100 -> 0
A20: 9 | B20: =INPUT!B20 -> 0 | K20: =IF(COUNT($F20:$J20)=0,"",SUM($F20:$J20)) | L20: =IF(ISERROR(IF($K20="","",ROUND(($K20/$K$10)*$L$10,2))),"",IF($K20="","",ROUND(($K20/$K$10)*$L$10,2))) | M20: =IF($L20="","",ROUND($L20*$M$10,2)) | Q20: =IF(COUNT($N20:$P20)=0,"",SUM($N20:$P20)) | R20: =IF(ISERROR(IF($Q20="","",ROUND(($Q20/$Q$10)*$R$10,2))),"",IF($Q20="","",ROUND(($Q20/$Q$10)*$R$10,2))) | S20: =IF($R20="","",ROUND($R20*$S$10,2)) | W20: =IF(COUNT($T20:$V20)=0,"",SUM($T20:$V20)) | X20: =IF(ISERROR(IF($W20="","",ROUND(($W20/$W$10)*$X$10,2))),"",IF($W20="","",ROUND(($W20/$W$10)*$X$10,2))) | Y20: =IF($X20="","",ROUND($X20*$Y$10,2)) | Z20: =IF(ISERROR(IF($V20="","",ROUND(SUM($M20,$S20,$Y20),2))),"",IF($V20="","",ROUND(SUM($M20,$S20,$Y20),2))) | AA20: =IF(ISERROR(IF($V20="","",VLOOKUP(Z20,NewTransmu,4,TRUE))),"",IF($V20="","",VLOOKUP(Z20,NewTransmu,4,TRUE))) | AB20: =IF(ISERROR(IF(AA20="","",VLOOKUP(AA20,DESCRIPTORS,4,TRUE))),"",IF(AA20="","",VLOOKUP(AA20,DESCRIPTORS,4,TRUE))) | AD20: Got below 75% | AE20: =AE14-AE18 -> 2 | AF20: =AF14-AF18 -> 1 | AG20: =AG14-AG18 -> 1 | AV20: =(T20/$T$10)*100 -> 0 | AW20: =(U20/$U$10)*100 -> 0 | AX20: =(V20/$V$10)*100 -> 0
A21: 10 | B21: =INPUT!B21 -> 0 | K21: =IF(COUNT($F21:$J21)=0,"",SUM($F21:$J21)) | L21: =IF(ISERROR(IF($K21="","",ROUND(($K21/$K$10)*$L$10,2))),"",IF($K21="","",ROUND(($K21/$K$10)*$L$10,2))) | M21: =IF($L21="","",ROUND($L21*$M$10,2)) | Q21: =IF(COUNT($N21:$P21)=0,"",SUM($N21:$P21)) | R21: =IF(ISERROR(IF($Q21="","",ROUND(($Q21/$Q$10)*$R$10,2))),"",IF($Q21="","",ROUND(($Q21/$Q$10)*$R$10,2))) | S21: =IF($R21="","",ROUND($R21*$S$10,2)) | W21: =IF(COUNT($T21:$V21)=0,"",SUM($T21:$V21)) | X21: =IF(ISERROR(IF($W21="","",ROUND(($W21/$W$10)*$X$10,2))),"",IF($W21="","",ROUND(($W21/$W$10)*$X$10,2))) | Y21: =IF($X21="","",ROUND($X21*$Y$10,2)) | Z21: =IF(ISERROR(IF($V21="","",ROUND(SUM($M21,$S21,$Y21),2))),"",IF($V21="","",ROUND(SUM($M21,$S21,$Y21),2))) | AA21: =IF(ISERROR(IF($V21="","",VLOOKUP(Z21,NewTransmu,4,TRUE))),"",IF($V21="","",VLOOKUP(Z21,NewTransmu,4,TRUE))) | AB21: =IF(ISERROR(IF(AA21="","",VLOOKUP(AA21,DESCRIPTORS,4,TRUE))),"",IF(AA21="","",VLOOKUP(AA21,DESCRIPTORS,4,TRUE))) | AD21: Percentage | AE21: =IFERROR(1-AE19,"") -> 0.33333333 | AF21: =IFERROR(1-AF19,"") -> 0.16666667 | AG21: =IFERROR(1-AG19,"") -> 0.16666667 | AV21: =(T21/$T$10)*100 -> 0 | AW21: =(U21/$U$10)*100 -> 0 | AX21: =(V21/$V$10)*100 -> 0
A22: 11 | B22: =INPUT!B22 -> 0 | K22: =IF(COUNT($F22:$J22)=0,"",SUM($F22:$J22)) | L22: =IF(ISERROR(IF($K22="","",ROUND(($K22/$K$10)*$L$10,2))),"",IF($K22="","",ROUND(($K22/$K$10)*$L$10,2))) | M22: =IF($L22="","",ROUND($L22*$M$10,2)) | Q22: =IF(COUNT($N22:$P22)=0,"",SUM($N22:$P22)) | R22: =IF(ISERROR(IF($Q22="","",ROUND(($Q22/$Q$10)*$R$10,2))),"",IF($Q22="","",ROUND(($Q22/$Q$10)*$R$10,2))) | S22: =IF($R22="","",ROUND($R22*$S$10,2)) | W22: =IF(COUNT($T22:$V22)=0,"",SUM($T22:$V22)) | X22: =IF(ISERROR(IF($W22="","",ROUND(($W22/$W$10)*$X$10,2))),"",IF($W22="","",ROUND(($W22/$W$10)*$X$10,2))) | Y22: =IF($X22="","",ROUND($X22*$Y$10,2)) | Z22: =IF(ISERROR(IF($V22="","",ROUND(SUM($M22,$S22,$Y22),2))),"",IF($V22="","",ROUND(SUM($M22,$S22,$Y22),2))) | AA22: =IF(ISERROR(IF($V22="","",VLOOKUP(Z22,NewTransmu,4,TRUE))),"",IF($V22="","",VLOOKUP(Z22,NewTransmu,4,TRUE))) | AB22: =IF(ISERROR(IF(AA22="","",VLOOKUP(AA22,DESCRIPTORS,4,TRUE))),"",IF(AA22="","",VLOOKUP(AA22,DESCRIPTORS,4,TRUE))) | AV22: =(T22/$T$10)*100 -> 0 | AW22: =(U22/$U$10)*100 -> 0 | AX22: =(V22/$V$10)*100 -> 0
A23: 12 | B23: =INPUT!B23 -> 0 | K23: =IF(COUNT($F23:$J23)=0,"",SUM($F23:$J23)) | L23: =IF(ISERROR(IF($K23="","",ROUND(($K23/$K$10)*$L$10,2))),"",IF($K23="","",ROUND(($K23/$K$10)*$L$10,2))) | M23: =IF($L23="","",ROUND($L23*$M$10,2)) | Q23: =IF(COUNT($N23:$P23)=0,"",SUM($N23:$P23)) | R23: =IF(ISERROR(IF($Q23="","",ROUND(($Q23/$Q$10)*$R$10,2))),"",IF($Q23="","",ROUND(($Q23/$Q$10)*$R$10,2))) | S23: =IF($R23="","",ROUND($R23*$S$10,2)) | W23: =IF(COUNT($T23:$V23)=0,"",SUM($T23:$V23)) | X23: =IF(ISERROR(IF($W23="","",ROUND(($W23/$W$10)*$X$10,2))),"",IF($W23="","",ROUND(($W23/$W$10)*$X$10,2))) | Y23: =IF($X23="","",ROUND($X23*$Y$10,2)) | Z23: =IF(ISERROR(IF($V23="","",ROUND(SUM($M23,$S23,$Y23),2))),"",IF($V23="","",ROUND(SUM($M23,$S23,$Y23),2))) | AA23: =IF(ISERROR(IF($V23="","",VLOOKUP(Z23,NewTransmu,4,TRUE))),"",IF($V23="","",VLOOKUP(Z23,NewTransmu,4,TRUE))) | AB23: =IF(ISERROR(IF(AA23="","",VLOOKUP(AA23,DESCRIPTORS,4,TRUE))),"",IF(AA23="","",VLOOKUP(AA23,DESCRIPTORS,4,TRUE))) | AD23: NORM-REFERENCED | AE23: ST1 | AF23: ST2 | AG23: TE | AV23: =(T23/$T$10)*100 -> 0 | AW23: =(U23/$U$10)*100 -> 0 | AX23: =(V23/$V$10)*100 -> 0
A24: 13 | B24: =INPUT!B24 -> 0 | K24: =IF(COUNT($F24:$J24)=0,"",SUM($F24:$J24)) | L24: =IF(ISERROR(IF($K24="","",ROUND(($K24/$K$10)*$L$10,2))),"",IF($K24="","",ROUND(($K24/$K$10)*$L$10,2))) | M24: =IF($L24="","",ROUND($L24*$M$10,2)) | Q24: =IF(COUNT($N24:$P24)=0,"",SUM($N24:$P24)) | R24: =IF(ISERROR(IF($Q24="","",ROUND(($Q24/$Q$10)*$R$10,2))),"",IF($Q24="","",ROUND(($Q24/$Q$10)*$R$10,2))) | S24: =IF($R24="","",ROUND($R24*$S$10,2)) | W24: =IF(COUNT($T24:$V24)=0,"",SUM($T24:$V24)) | X24: =IF(ISERROR(IF($W24="","",ROUND(($W24/$W$10)*$X$10,2))),"",IF($W24="","",ROUND(($W24/$W$10)*$X$10,2))) | Y24: =IF($X24="","",ROUND($X24*$Y$10,2)) | Z24: =IF(ISERROR(IF($V24="","",ROUND(SUM($M24,$S24,$Y24),2))),"",IF($V24="","",ROUND(SUM($M24,$S24,$Y24),2))) | AA24: =IF(ISERROR(IF($V24="","",VLOOKUP(Z24,NewTransmu,4,TRUE))),"",IF($V24="","",VLOOKUP(Z24,NewTransmu,4,TRUE))) | AB24: =IF(ISERROR(IF(AA24="","",VLOOKUP(AA24,DESCRIPTORS,4,TRUE))),"",IF(AA24="","",VLOOKUP(AA24,DESCRIPTORS,4,TRUE))) | AD24: Mean | AE24: =IFERROR(AVERAGE(T12:T112),"") -> 38.833333 | AF24: =IFERROR(AVERAGE(U12:U112),"") -> 38.333333 | AG24: =IFERROR(AVERAGE(V12:V112),"") -> 40.5 | AV24: =(T24/$T$10)*100 -> 0 | AW24: =(U24/$U$10)*100 -> 0 | AX24: =(V24/$V$10)*100 -> 0
A25: 14 | B25: =INPUT!B25 -> 0 | K25: =IF(COUNT($F25:$J25)=0,"",SUM($F25:$J25)) | L25: =IF(ISERROR(IF($K25="","",ROUND(($K25/$K$10)*$L$10,2))),"",IF($K25="","",ROUND(($K25/$K$10)*$L$10,2))) | M25: =IF($L25="","",ROUND($L25*$M$10,2)) | Q25: =IF(COUNT($N25:$P25)=0,"",SUM($N25:$P25)) | R25: =IF(ISERROR(IF($Q25="","",ROUND(($Q25/$Q$10)*$R$10,2))),"",IF($Q25="","",ROUND(($Q25/$Q$10)*$R$10,2))) | S25: =IF($R25="","",ROUND($R25*$S$10,2)) | W25: =IF(COUNT($T25:$V25)=0,"",SUM($T25:$V25)) | X25: =IF(ISERROR(IF($W25="","",ROUND(($W25/$W$10)*$X$10,2))),"",IF($W25="","",ROUND(($W25/$W$10)*$X$10,2))) | Y25: =IF($X25="","",ROUND($X25*$Y$10,2)) | Z25: =IF(ISERROR(IF($V25="","",ROUND(SUM($M25,$S25,$Y25),2))),"",IF($V25="","",ROUND(SUM($M25,$S25,$Y25),2))) | AA25: =IF(ISERROR(IF($V25="","",VLOOKUP(Z25,NewTransmu,4,TRUE))),"",IF($V25="","",VLOOKUP(Z25,NewTransmu,4,TRUE))) | AB25: =IF(ISERROR(IF(AA25="","",VLOOKUP(AA25,DESCRIPTORS,4,TRUE))),"",IF(AA25="","",VLOOKUP(AA25,DESCRIPTORS,4,TRUE))) | AD25: Median | AE25: =IFERROR(MEDIAN(T12:T112),"") -> 40 | AF25: =IFERROR(MEDIAN(U12:U112),"") -> 39 | AG25: =IFERROR(MEDIAN(V12:V112),"") -> 42 | AV25: =(T25/$T$10)*100 -> 0 | AW25: =(U25/$U$10)*100 -> 0 | AX25: =(V25/$V$10)*100 -> 0
A26: 15 | B26: =INPUT!B26 -> 0 | K26: =IF(COUNT($F26:$J26)=0,"",SUM($F26:$J26)) | L26: =IF(ISERROR(IF($K26="","",ROUND(($K26/$K$10)*$L$10,2))),"",IF($K26="","",ROUND(($K26/$K$10)*$L$10,2))) | M26: =IF($L26="","",ROUND($L26*$M$10,2)) | Q26: =IF(COUNT($N26:$P26)=0,"",SUM($N26:$P26)) | R26: =IF(ISERROR(IF($Q26="","",ROUND(($Q26/$Q$10)*$R$10,2))),"",IF($Q26="","",ROUND(($Q26/$Q$10)*$R$10,2))) | S26: =IF($R26="","",ROUND($R26*$S$10,2)) | W26: =IF(COUNT($T26:$V26)=0,"",SUM($T26:$V26)) | X26: =IF(ISERROR(IF($W26="","",ROUND(($W26/$W$10)*$X$10,2))),"",IF($W26="","",ROUND(($W26/$W$10)*$X$10,2))) | Y26: =IF($X26="","",ROUND($X26*$Y$10,2)) | Z26: =IF(ISERROR(IF($V26="","",ROUND(SUM($M26,$S26,$Y26),2))),"",IF($V26="","",ROUND(SUM($M26,$S26,$Y26),2))) | AA26: =IF(ISERROR(IF($V26="","",VLOOKUP(Z26,NewTransmu,4,TRUE))),"",IF($V26="","",VLOOKUP(Z26,NewTransmu,4,TRUE))) | AB26: =IF(ISERROR(IF(AA26="","",VLOOKUP(AA26,DESCRIPTORS,4,TRUE))),"",IF(AA26="","",VLOOKUP(AA26,DESCRIPTORS,4,TRUE))) | AD26: SD | AE26: =IFERROR(_xlfn.STDEV.S(T12:T112),"") -> 5.492419 | AF26: =_xlfn.STDEV.S(U12:U112) -> 4.2739521 | AG26: =_xlfn.STDEV.S(V12:V112) -> 5.5767374 | AV26: =(T26/$T$10)*100 -> 0 | AW26: =(U26/$U$10)*100 -> 0 | AX26: =(V26/$V$10)*100 -> 0
A27: 16 | B27: =INPUT!B27 -> 0 | K27: =IF(COUNT($F27:$J27)=0,"",SUM($F27:$J27)) | L27: =IF(ISERROR(IF($K27="","",ROUND(($K27/$K$10)*$L$10,2))),"",IF($K27="","",ROUND(($K27/$K$10)*$L$10,2))) | M27: =IF($L27="","",ROUND($L27*$M$10,2)) | Q27: =IF(COUNT($N27:$P27)=0,"",SUM($N27:$P27)) | R27: =IF(ISERROR(IF($Q27="","",ROUND(($Q27/$Q$10)*$R$10,2))),"",IF($Q27="","",ROUND(($Q27/$Q$10)*$R$10,2))) | S27: =IF($R27="","",ROUND($R27*$S$10,2)) | W27: =IF(COUNT($T27:$V27)=0,"",SUM($T27:$V27)) | X27: =IF(ISERROR(IF($W27="","",ROUND(($W27/$W$10)*$X$10,2))),"",IF($W27="","",ROUND(($W27/$W$10)*$X$10,2))) | Y27: =IF($X27="","",ROUND($X27*$Y$10,2)) | Z27: =IF(ISERROR(IF($V27="","",ROUND(SUM($M27,$S27,$Y27),2))),"",IF($V27="","",ROUND(SUM($M27,$S27,$Y27),2))) | AA27: =IF(ISERROR(IF($V27="","",VLOOKUP(Z27,NewTransmu,4,TRUE))),"",IF($V27="","",VLOOKUP(Z27,NewTransmu,4,TRUE))) | AB27: =IF(ISERROR(IF(AA27="","",VLOOKUP(AA27,DESCRIPTORS,4,TRUE))),"",IF(AA27="","",VLOOKUP(AA27,DESCRIPTORS,4,TRUE))) | AD27: MPS/PL | AE27: =IFERROR(AE24/AE15,"") -> 0.77666667 | AF27: =IFERROR(AF24/AF15,"") -> 0.76666667 | AG27: =IFERROR(AG24/AG15,"") -> 0.81 | AV27: =(T27/$T$10)*100 -> 0 | AW27: =(U27/$U$10)*100 -> 0 | AX27: =(V27/$V$10)*100 -> 0
A28: 17 | B28: =INPUT!B28 -> 0 | K28: =IF(COUNT($F28:$J28)=0,"",SUM($F28:$J28)) | L28: =IF(ISERROR(IF($K28="","",ROUND(($K28/$K$10)*$L$10,2))),"",IF($K28="","",ROUND(($K28/$K$10)*$L$10,2))) | M28: =IF($L28="","",ROUND($L28*$M$10,2)) | Q28: =IF(COUNT($N28:$P28)=0,"",SUM($N28:$P28)) | R28: =IF(ISERROR(IF($Q28="","",ROUND(($Q28/$Q$10)*$R$10,2))),"",IF($Q28="","",ROUND(($Q28/$Q$10)*$R$10,2))) | S28: =IF($R28="","",ROUND($R28*$S$10,2)) | W28: =IF(COUNT($T28:$V28)=0,"",SUM($T28:$V28)) | X28: =IF(ISERROR(IF($W28="","",ROUND(($W28/$W$10)*$X$10,2))),"",IF($W28="","",ROUND(($W28/$W$10)*$X$10,2))) | Y28: =IF($X28="","",ROUND($X28*$Y$10,2)) | Z28: =IF(ISERROR(IF($V28="","",ROUND(SUM($M28,$S28,$Y28),2))),"",IF($V28="","",ROUND(SUM($M28,$S28,$Y28),2))) | AA28: =IF(ISERROR(IF($V28="","",VLOOKUP(Z28,NewTransmu,4,TRUE))),"",IF($V28="","",VLOOKUP(Z28,NewTransmu,4,TRUE))) | AB28: =IF(ISERROR(IF(AA28="","",VLOOKUP(AA28,DESCRIPTORS,4,TRUE))),"",IF(AA28="","",VLOOKUP(AA28,DESCRIPTORS,4,TRUE))) | AV28: =(T28/$T$10)*100 -> 0 | AW28: =(U28/$U$10)*100 -> 0 | AX28: =(V28/$V$10)*100 -> 0
A29: 18 | B29: =INPUT!B29 -> 0 | K29: =IF(COUNT($F29:$J29)=0,"",SUM($F29:$J29)) | L29: =IF(ISERROR(IF($K29="","",ROUND(($K29/$K$10)*$L$10,2))),"",IF($K29="","",ROUND(($K29/$K$10)*$L$10,2))) | M29: =IF($L29="","",ROUND($L29*$M$10,2)) | Q29: =IF(COUNT($N29:$P29)=0,"",SUM($N29:$P29)) | R29: =IF(ISERROR(IF($Q29="","",ROUND(($Q29/$Q$10)*$R$10,2))),"",IF($Q29="","",ROUND(($Q29/$Q$10)*$R$10,2))) | S29: =IF($R29="","",ROUND($R29*$S$10,2)) | W29: =IF(COUNT($T29:$V29)=0,"",SUM($T29:$V29)) | X29: =IF(ISERROR(IF($W29="","",ROUND(($W29/$W$10)*$X$10,2))),"",IF($W29="","",ROUND(($W29/$W$10)*$X$10,2))) | Y29: =IF($X29="","",ROUND($X29*$Y$10,2)) | Z29: =IF(ISERROR(IF($V29="","",ROUND(SUM($M29,$S29,$Y29),2))),"",IF($V29="","",ROUND(SUM($M29,$S29,$Y29),2))) | AA29: =IF(ISERROR(IF($V29="","",VLOOKUP(Z29,NewTransmu,4,TRUE))),"",IF($V29="","",VLOOKUP(Z29,NewTransmu,4,TRUE))) | AB29: =IF(ISERROR(IF(AA29="","",VLOOKUP(AA29,DESCRIPTORS,4,TRUE))),"",IF(AA29="","",VLOOKUP(AA29,DESCRIPTORS,4,TRUE))) | AD29: OTHER INFO | AE29: ST1 | AF29: ST2 | AG29: TE | AV29: =(T29/$T$10)*100 -> 0 | AW29: =(U29/$U$10)*100 -> 0 | AX29: =(V29/$V$10)*100 -> 0
A30: 19 | B30: =INPUT!B30 -> 0 | K30: =IF(COUNT($F30:$J30)=0,"",SUM($F30:$J30)) | L30: =IF(ISERROR(IF($K30="","",ROUND(($K30/$K$10)*$L$10,2))),"",IF($K30="","",ROUND(($K30/$K$10)*$L$10,2))) | M30: =IF($L30="","",ROUND($L30*$M$10,2)) | Q30: =IF(COUNT($N30:$P30)=0,"",SUM($N30:$P30)) | R30: =IF(ISERROR(IF($Q30="","",ROUND(($Q30/$Q$10)*$R$10,2))),"",IF($Q30="","",ROUND(($Q30/$Q$10)*$R$10,2))) | S30: =IF($R30="","",ROUND($R30*$S$10,2)) | W30: =IF(COUNT($T30:$V30)=0,"",SUM($T30:$V30)) | X30: =IF(ISERROR(IF($W30="","",ROUND(($W30/$W$10)*$X$10,2))),"",IF($W30="","",ROUND(($W30/$W$10)*$X$10,2))) | Y30: =IF($X30="","",ROUND($X30*$Y$10,2)) | Z30: =IF(ISERROR(IF($V30="","",ROUND(SUM($M30,$S30,$Y30),2))),"",IF($V30="","",ROUND(SUM($M30,$S30,$Y30),2))) | AA30: =IF(ISERROR(IF($V30="","",VLOOKUP(Z30,NewTransmu,4,TRUE))),"",IF($V30="","",VLOOKUP(Z30,NewTransmu,4,TRUE))) | AB30: =IF(ISERROR(IF(AA30="","",VLOOKUP(AA30,DESCRIPTORS,4,TRUE))),"",IF(AA30="","",VLOOKUP(AA30,DESCRIPTORS,4,TRUE))) | AD30: Highest Score | AE30: =IF(COUNTA(T12:T112)=0,"",MAX(T12:T112)) -> 45 | AF30: =IF(COUNTA(U12:U112)=0,"",MAX(U12:U112)) -> 42 | AG30: =IF(COUNTA(V12:V112)=0,"",MAX(V12:V112)) -> 45 | AV30: =(T30/$T$10)*100 -> 0 | AW30: =(U30/$U$10)*100 -> 0 | AX30: =(V30/$V$10)*100 -> 0
A31: 20 | B31: =INPUT!B31 -> 0 | K31: =IF(COUNT($F31:$J31)=0,"",SUM($F31:$J31)) | L31: =IF(ISERROR(IF($K31="","",ROUND(($K31/$K$10)*$L$10,2))),"",IF($K31="","",ROUND(($K31/$K$10)*$L$10,2))) | M31: =IF($L31="","",ROUND($L31*$M$10,2)) | Q31: =IF(COUNT($N31:$P31)=0,"",SUM($N31:$P31)) | R31: =IF(ISERROR(IF($Q31="","",ROUND(($Q31/$Q$10)*$R$10,2))),"",IF($Q31="","",ROUND(($Q31/$Q$10)*$R$10,2))) | S31: =IF($R31="","",ROUND($R31*$S$10,2)) | W31: =IF(COUNT($T31:$V31)=0,"",SUM($T31:$V31)) | X31: =IF(ISERROR(IF($W31="","",ROUND(($W31/$W$10)*$X$10,2))),"",IF($W31="","",ROUND(($W31/$W$10)*$X$10,2))) | Y31: =IF($X31="","",ROUND($X31*$Y$10,2)) | Z31: =IF(ISERROR(IF($V31="","",ROUND(SUM($M31,$S31,$Y31),2))),"",IF($V31="","",ROUND(SUM($M31,$S31,$Y31),2))) | AA31: =IF(ISERROR(IF($V31="","",VLOOKUP(Z31,NewTransmu,4,TRUE))),"",IF($V31="","",VLOOKUP(Z31,NewTransmu,4,TRUE))) | AB31: =IF(ISERROR(IF(AA31="","",VLOOKUP(AA31,DESCRIPTORS,4,TRUE))),"",IF(AA31="","",VLOOKUP(AA31,DESCRIPTORS,4,TRUE))) | AD31: Lowest Score | AE31: =IF(COUNTA(T12:T112)=0,"",MIN(T12:T112)) -> 30 | AF31: =IF(COUNTA(U12:U112)=0,"",MIN(U12:U112)) -> 30 | AG31: =IF(COUNTA(V12:V112)=0,"",MIN(V12:V112)) -> 30 | AV31: =(T31/$T$10)*100 -> 0 | AW31: =(U31/$U$10)*100 -> 0 | AX31: =(V31/$V$10)*100 -> 0
A32: 21 | B32: =INPUT!B32 -> 0 | K32: =IF(COUNT($F32:$J32)=0,"",SUM($F32:$J32)) | L32: =IF(ISERROR(IF($K32="","",ROUND(($K32/$K$10)*$L$10,2))),"",IF($K32="","",ROUND(($K32/$K$10)*$L$10,2))) | M32: =IF($L32="","",ROUND($L32*$M$10,2)) | Q32: =IF(COUNT($N32:$P32)=0,"",SUM($N32:$P32)) | R32: =IF(ISERROR(IF($Q32="","",ROUND(($Q32/$Q$10)*$R$10,2))),"",IF($Q32="","",ROUND(($Q32/$Q$10)*$R$10,2))) | S32: =IF($R32="","",ROUND($R32*$S$10,2)) | W32: =IF(COUNT($T32:$V32)=0,"",SUM($T32:$V32)) | X32: =IF(ISERROR(IF($W32="","",ROUND(($W32/$W$10)*$X$10,2))),"",IF($W32="","",ROUND(($W32/$W$10)*$X$10,2))) | Y32: =IF($X32="","",ROUND($X32*$Y$10,2)) | Z32: =IF(ISERROR(IF($V32="","",ROUND(SUM($M32,$S32,$Y32),2))),"",IF($V32="","",ROUND(SUM($M32,$S32,$Y32),2))) | AA32: =IF(ISERROR(IF($V32="","",VLOOKUP(Z32,NewTransmu,4,TRUE))),"",IF($V32="","",VLOOKUP(Z32,NewTransmu,4,TRUE))) | AB32: =IF(ISERROR(IF(AA32="","",VLOOKUP(AA32,DESCRIPTORS,4,TRUE))),"",IF(AA32="","",VLOOKUP(AA32,DESCRIPTORS,4,TRUE))) | AD32: Total Score | AE32: =IF(COUNTA(T12:T112)=0,"",SUM(T12:T112)) -> 233 | AF32: =IF(COUNTA(U12:U112)=0,"",SUM(U12:U112)) -> 230 | AG32: =IF(COUNTA(V12:V112)=0,"",SUM(V12:V112)) -> 243 | AV32: =(T32/$T$10)*100 -> 0 | AW32: =(U32/$U$10)*100 -> 0 | AX32: =(V32/$V$10)*100 -> 0
A33: 22 | B33: =INPUT!B33 -> 0 | K33: =IF(COUNT($F33:$J33)=0,"",SUM($F33:$J33)) | L33: =IF(ISERROR(IF($K33="","",ROUND(($K33/$K$10)*$L$10,2))),"",IF($K33="","",ROUND(($K33/$K$10)*$L$10,2))) | M33: =IF($L33="","",ROUND($L33*$M$10,2)) | Q33: =IF(COUNT($N33:$P33)=0,"",SUM($N33:$P33)) | R33: =IF(ISERROR(IF($Q33="","",ROUND(($Q33/$Q$10)*$R$10,2))),"",IF($Q33="","",ROUND(($Q33/$Q$10)*$R$10,2))) | S33: =IF($R33="","",ROUND($R33*$S$10,2)) | W33: =IF(COUNT($T33:$V33)=0,"",SUM($T33:$V33)) | X33: =IF(ISERROR(IF($W33="","",ROUND(($W33/$W$10)*$X$10,2))),"",IF($W33="","",ROUND(($W33/$W$10)*$X$10,2))) | Y33: =IF($X33="","",ROUND($X33*$Y$10,2)) | Z33: =IF(ISERROR(IF($V33="","",ROUND(SUM($M33,$S33,$Y33),2))),"",IF($V33="","",ROUND(SUM($M33,$S33,$Y33),2))) | AA33: =IF(ISERROR(IF($V33="","",VLOOKUP(Z33,NewTransmu,4,TRUE))),"",IF($V33="","",VLOOKUP(Z33,NewTransmu,4,TRUE))) | AB33: =IF(ISERROR(IF(AA33="","",VLOOKUP(AA33,DESCRIPTORS,4,TRUE))),"",IF(AA33="","",VLOOKUP(AA33,DESCRIPTORS,4,TRUE))) | AV33: =(T33/$T$10)*100 -> 0 | AW33: =(U33/$U$10)*100 -> 0 | AX33: =(V33/$V$10)*100 -> 0
A34: 23 | B34: =INPUT!B34 -> 0 | K34: =IF(COUNT($F34:$J34)=0,"",SUM($F34:$J34)) | L34: =IF(ISERROR(IF($K34="","",ROUND(($K34/$K$10)*$L$10,2))),"",IF($K34="","",ROUND(($K34/$K$10)*$L$10,2))) | M34: =IF($L34="","",ROUND($L34*$M$10,2)) | Q34: =IF(COUNT($N34:$P34)=0,"",SUM($N34:$P34)) | R34: =IF(ISERROR(IF($Q34="","",ROUND(($Q34/$Q$10)*$R$10,2))),"",IF($Q34="","",ROUND(($Q34/$Q$10)*$R$10,2))) | S34: =IF($R34="","",ROUND($R34*$S$10,2)) | W34: =IF(COUNT($T34:$V34)=0,"",SUM($T34:$V34)) | X34: =IF(ISERROR(IF($W34="","",ROUND(($W34/$W$10)*$X$10,2))),"",IF($W34="","",ROUND(($W34/$W$10)*$X$10,2))) | Y34: =IF($X34="","",ROUND($X34*$Y$10,2)) | Z34: =IF(ISERROR(IF($V34="","",ROUND(SUM($M34,$S34,$Y34),2))),"",IF($V34="","",ROUND(SUM($M34,$S34,$Y34),2))) | AA34: =IF(ISERROR(IF($V34="","",VLOOKUP(Z34,NewTransmu,4,TRUE))),"",IF($V34="","",VLOOKUP(Z34,NewTransmu,4,TRUE))) | AB34: =IF(ISERROR(IF(AA34="","",VLOOKUP(AA34,DESCRIPTORS,4,TRUE))),"",IF(AA34="","",VLOOKUP(AA34,DESCRIPTORS,4,TRUE))) | AV34: =(T34/$T$10)*100 -> 0 | AW34: =(U34/$U$10)*100 -> 0 | AX34: =(V34/$V$10)*100 -> 0
A35: 24 | B35: =INPUT!B35 -> 0 | K35: =IF(COUNT($F35:$J35)=0,"",SUM($F35:$J35)) | L35: =IF(ISERROR(IF($K35="","",ROUND(($K35/$K$10)*$L$10,2))),"",IF($K35="","",ROUND(($K35/$K$10)*$L$10,2))) | M35: =IF($L35="","",ROUND($L35*$M$10,2)) | Q35: =IF(COUNT($N35:$P35)=0,"",SUM($N35:$P35)) | R35: =IF(ISERROR(IF($Q35="","",ROUND(($Q35/$Q$10)*$R$10,2))),"",IF($Q35="","",ROUND(($Q35/$Q$10)*$R$10,2))) | S35: =IF($R35="","",ROUND($R35*$S$10,2)) | W35: =IF(COUNT($T35:$V35)=0,"",SUM($T35:$V35)) | X35: =IF(ISERROR(IF($W35="","",ROUND(($W35/$W$10)*$X$10,2))),"",IF($W35="","",ROUND(($W35/$W$10)*$X$10,2))) | Y35: =IF($X35="","",ROUND($X35*$Y$10,2)) | Z35: =IF(ISERROR(IF($V35="","",ROUND(SUM($M35,$S35,$Y35),2))),"",IF($V35="","",ROUND(SUM($M35,$S35,$Y35),2))) | AA35: =IF(ISERROR(IF($V35="","",VLOOKUP(Z35,NewTransmu,4,TRUE))),"",IF($V35="","",VLOOKUP(Z35,NewTransmu,4,TRUE))) | AB35: =IF(ISERROR(IF(AA35="","",VLOOKUP(AA35,DESCRIPTORS,4,TRUE))),"",IF(AA35="","",VLOOKUP(AA35,DESCRIPTORS,4,TRUE))) | AV35: =(T35/$T$10)*100 -> 0 | AW35: =(U35/$U$10)*100 -> 0 | AX35: =(V35/$V$10)*100 -> 0
A36: 25 | B36: =INPUT!B36 -> 0 | K36: =IF(COUNT($F36:$J36)=0,"",SUM($F36:$J36)) | L36: =IF(ISERROR(IF($K36="","",ROUND(($K36/$K$10)*$L$10,2))),"",IF($K36="","",ROUND(($K36/$K$10)*$L$10,2))) | M36: =IF($L36="","",ROUND($L36*$M$10,2)) | Q36: =IF(COUNT($N36:$P36)=0,"",SUM($N36:$P36)) | R36: =IF(ISERROR(IF($Q36="","",ROUND(($Q36/$Q$10)*$R$10,2))),"",IF($Q36="","",ROUND(($Q36/$Q$10)*$R$10,2))) | S36: =IF($R36="","",ROUND($R36*$S$10,2)) | W36: =IF(COUNT($T36:$V36)=0,"",SUM($T36:$V36)) | X36: =IF(ISERROR(IF($W36="","",ROUND(($W36/$W$10)*$X$10,2))),"",IF($W36="","",ROUND(($W36/$W$10)*$X$10,2))) | Y36: =IF($X36="","",ROUND($X36*$Y$10,2)) | Z36: =IF(ISERROR(IF($V36="","",ROUND(SUM($M36,$S36,$Y36),2))),"",IF($V36="","",ROUND(SUM($M36,$S36,$Y36),2))) | AA36: =IF(ISERROR(IF($V36="","",VLOOKUP(Z36,NewTransmu,4,TRUE))),"",IF($V36="","",VLOOKUP(Z36,NewTransmu,4,TRUE))) | AB36: =IF(ISERROR(IF(AA36="","",VLOOKUP(AA36,DESCRIPTORS,4,TRUE))),"",IF(AA36="","",VLOOKUP(AA36,DESCRIPTORS,4,TRUE))) | AV36: =(T36/$T$10)*100 -> 0 | AW36: =(U36/$U$10)*100 -> 0 | AX36: =(V36/$V$10)*100 -> 0
A37: 26 | B37: =INPUT!B37 -> 0 | K37: =IF(COUNT($F37:$J37)=0,"",SUM($F37:$J37)) | L37: =IF(ISERROR(IF($K37="","",ROUND(($K37/$K$10)*$L$10,2))),"",IF($K37="","",ROUND(($K37/$K$10)*$L$10,2))) | M37: =IF($L37="","",ROUND($L37*$M$10,2)) | Q37: =IF(COUNT($N37:$P37)=0,"",SUM($N37:$P37)) | R37: =IF(ISERROR(IF($Q37="","",ROUND(($Q37/$Q$10)*$R$10,2))),"",IF($Q37="","",ROUND(($Q37/$Q$10)*$R$10,2))) | S37: =IF($R37="","",ROUND($R37*$S$10,2)) | W37: =IF(COUNT($T37:$V37)=0,"",SUM($T37:$V37)) | X37: =IF(ISERROR(IF($W37="","",ROUND(($W37/$W$10)*$X$10,2))),"",IF($W37="","",ROUND(($W37/$W$10)*$X$10,2))) | Y37: =IF($X37="","",ROUND($X37*$Y$10,2)) | Z37: =IF(ISERROR(IF($V37="","",ROUND(SUM($M37,$S37,$Y37),2))),"",IF($V37="","",ROUND(SUM($M37,$S37,$Y37),2))) | AA37: =IF(ISERROR(IF($V37="","",VLOOKUP(Z37,NewTransmu,4,TRUE))),"",IF($V37="","",VLOOKUP(Z37,NewTransmu,4,TRUE))) | AB37: =IF(ISERROR(IF(AA37="","",VLOOKUP(AA37,DESCRIPTORS,4,TRUE))),"",IF(AA37="","",VLOOKUP(AA37,DESCRIPTORS,4,TRUE))) | AV37: =(T37/$T$10)*100 -> 0 | AW37: =(U37/$U$10)*100 -> 0 | AX37: =(V37/$V$10)*100 -> 0
A38: 27 | B38: =INPUT!B38 -> 0 | K38: =IF(COUNT($F38:$J38)=0,"",SUM($F38:$J38)) | L38: =IF(ISERROR(IF($K38="","",ROUND(($K38/$K$10)*$L$10,2))),"",IF($K38="","",ROUND(($K38/$K$10)*$L$10,2))) | M38: =IF($L38="","",ROUND($L38*$M$10,2)) | Q38: =IF(COUNT($N38:$P38)=0,"",SUM($N38:$P38)) | R38: =IF(ISERROR(IF($Q38="","",ROUND(($Q38/$Q$10)*$R$10,2))),"",IF($Q38="","",ROUND(($Q38/$Q$10)*$R$10,2))) | S38: =IF($R38="","",ROUND($R38*$S$10,2)) | W38: =IF(COUNT($T38:$V38)=0,"",SUM($T38:$V38)) | X38: =IF(ISERROR(IF($W38="","",ROUND(($W38/$W$10)*$X$10,2))),"",IF($W38="","",ROUND(($W38/$W$10)*$X$10,2))) | Y38: =IF($X38="","",ROUND($X38*$Y$10,2)) | Z38: =IF(ISERROR(IF($V38="","",ROUND(SUM($M38,$S38,$Y38),2))),"",IF($V38="","",ROUND(SUM($M38,$S38,$Y38),2))) | AA38: =IF(ISERROR(IF($V38="","",VLOOKUP(Z38,NewTransmu,4,TRUE))),"",IF($V38="","",VLOOKUP(Z38,NewTransmu,4,TRUE))) | AB38: =IF(ISERROR(IF(AA38="","",VLOOKUP(AA38,DESCRIPTORS,4,TRUE))),"",IF(AA38="","",VLOOKUP(AA38,DESCRIPTORS,4,TRUE))) | AV38: =(T38/$T$10)*100 -> 0 | AW38: =(U38/$U$10)*100 -> 0 | AX38: =(V38/$V$10)*100 -> 0
A39: 28 | B39: =INPUT!B39 -> 0 | K39: =IF(COUNT($F39:$J39)=0,"",SUM($F39:$J39)) | L39: =IF(ISERROR(IF($K39="","",ROUND(($K39/$K$10)*$L$10,2))),"",IF($K39="","",ROUND(($K39/$K$10)*$L$10,2))) | M39: =IF($L39="","",ROUND($L39*$M$10,2)) | Q39: =IF(COUNT($N39:$P39)=0,"",SUM($N39:$P39)) | R39: =IF(ISERROR(IF($Q39="","",ROUND(($Q39/$Q$10)*$R$10,2))),"",IF($Q39="","",ROUND(($Q39/$Q$10)*$R$10,2))) | S39: =IF($R39="","",ROUND($R39*$S$10,2)) | W39: =IF(COUNT($T39:$V39)=0,"",SUM($T39:$V39)) | X39: =IF(ISERROR(IF($W39="","",ROUND(($W39/$W$10)*$X$10,2))),"",IF($W39="","",ROUND(($W39/$W$10)*$X$10,2))) | Y39: =IF($X39="","",ROUND($X39*$Y$10,2)) | Z39: =IF(ISERROR(IF($V39="","",ROUND(SUM($M39,$S39,$Y39),2))),"",IF($V39="","",ROUND(SUM($M39,$S39,$Y39),2))) | AA39: =IF(ISERROR(IF($V39="","",VLOOKUP(Z39,NewTransmu,4,TRUE))),"",IF($V39="","",VLOOKUP(Z39,NewTransmu,4,TRUE))) | AB39: =IF(ISERROR(IF(AA39="","",VLOOKUP(AA39,DESCRIPTORS,4,TRUE))),"",IF(AA39="","",VLOOKUP(AA39,DESCRIPTORS,4,TRUE))) | AV39: =(T39/$T$10)*100 -> 0 | AW39: =(U39/$U$10)*100 -> 0 | AX39: =(V39/$V$10)*100 -> 0
A40: 29 | B40: =INPUT!B40 -> 0 | K40: =IF(COUNT($F40:$J40)=0,"",SUM($F40:$J40)) | L40: =IF(ISERROR(IF($K40="","",ROUND(($K40/$K$10)*$L$10,2))),"",IF($K40="","",ROUND(($K40/$K$10)*$L$10,2))) | M40: =IF($L40="","",ROUND($L40*$M$10,2)) | Q40: =IF(COUNT($N40:$P40)=0,"",SUM($N40:$P40)) | R40: =IF(ISERROR(IF($Q40="","",ROUND(($Q40/$Q$10)*$R$10,2))),"",IF($Q40="","",ROUND(($Q40/$Q$10)*$R$10,2))) | S40: =IF($R40="","",ROUND($R40*$S$10,2)) | W40: =IF(COUNT($T40:$V40)=0,"",SUM($T40:$V40)) | X40: =IF(ISERROR(IF($W40="","",ROUND(($W40/$W$10)*$X$10,2))),"",IF($W40="","",ROUND(($W40/$W$10)*$X$10,2))) | Y40: =IF($X40="","",ROUND($X40*$Y$10,2)) | Z40: =IF(ISERROR(IF($V40="","",ROUND(SUM($M40,$S40,$Y40),2))),"",IF($V40="","",ROUND(SUM($M40,$S40,$Y40),2))) | AA40: =IF(ISERROR(IF($V40="","",VLOOKUP(Z40,NewTransmu,4,TRUE))),"",IF($V40="","",VLOOKUP(Z40,NewTransmu,4,TRUE))) | AB40: =IF(ISERROR(IF(AA40="","",VLOOKUP(AA40,DESCRIPTORS,4,TRUE))),"",IF(AA40="","",VLOOKUP(AA40,DESCRIPTORS,4,TRUE))) | AV40: =(T40/$T$10)*100 -> 0 | AW40: =(U40/$U$10)*100 -> 0 | AX40: =(V40/$V$10)*100 -> 0
A41: 30 | B41: =INPUT!B41 -> 0 | K41: =IF(COUNT($F41:$J41)=0,"",SUM($F41:$J41)) | L41: =IF(ISERROR(IF($K41="","",ROUND(($K41/$K$10)*$L$10,2))),"",IF($K41="","",ROUND(($K41/$K$10)*$L$10,2))) | M41: =IF($L41="","",ROUND($L41*$M$10,2)) | Q41: =IF(COUNT($N41:$P41)=0,"",SUM($N41:$P41)) | R41: =IF(ISERROR(IF($Q41="","",ROUND(($Q41/$Q$10)*$R$10,2))),"",IF($Q41="","",ROUND(($Q41/$Q$10)*$R$10,2))) | S41: =IF($R41="","",ROUND($R41*$S$10,2)) | W41: =IF(COUNT($T41:$V41)=0,"",SUM($T41:$V41)) | X41: =IF(ISERROR(IF($W41="","",ROUND(($W41/$W$10)*$X$10,2))),"",IF($W41="","",ROUND(($W41/$W$10)*$X$10,2))) | Y41: =IF($X41="","",ROUND($X41*$Y$10,2)) | Z41: =IF(ISERROR(IF($V41="","",ROUND(SUM($M41,$S41,$Y41),2))),"",IF($V41="","",ROUND(SUM($M41,$S41,$Y41),2))) | AA41: =IF(ISERROR(IF($V41="","",VLOOKUP(Z41,NewTransmu,4,TRUE))),"",IF($V41="","",VLOOKUP(Z41,NewTransmu,4,TRUE))) | AB41: =IF(ISERROR(IF(AA41="","",VLOOKUP(AA41,DESCRIPTORS,4,TRUE))),"",IF(AA41="","",VLOOKUP(AA41,DESCRIPTORS,4,TRUE))) | AV41: =(T41/$T$10)*100 -> 0 | AW41: =(U41/$U$10)*100 -> 0 | AX41: =(V41/$V$10)*100 -> 0
A42: 31 | B42: =INPUT!B42 -> 0 | K42: =IF(COUNT($F42:$J42)=0,"",SUM($F42:$J42)) | L42: =IF(ISERROR(IF($K42="","",ROUND(($K42/$K$10)*$L$10,2))),"",IF($K42="","",ROUND(($K42/$K$10)*$L$10,2))) | M42: =IF($L42="","",ROUND($L42*$M$10,2)) | Q42: =IF(COUNT($N42:$P42)=0,"",SUM($N42:$P42)) | R42: =IF(ISERROR(IF($Q42="","",ROUND(($Q42/$Q$10)*$R$10,2))),"",IF($Q42="","",ROUND(($Q42/$Q$10)*$R$10,2))) | S42: =IF($R42="","",ROUND($R42*$S$10,2)) | W42: =IF(COUNT($T42:$V42)=0,"",SUM($T42:$V42)) | X42: =IF(ISERROR(IF($W42="","",ROUND(($W42/$W$10)*$X$10,2))),"",IF($W42="","",ROUND(($W42/$W$10)*$X$10,2))) | Y42: =IF($X42="","",ROUND($X42*$Y$10,2)) | Z42: =IF(ISERROR(IF($V42="","",ROUND(SUM($M42,$S42,$Y42),2))),"",IF($V42="","",ROUND(SUM($M42,$S42,$Y42),2))) | AA42: =IF(ISERROR(IF($V42="","",VLOOKUP(Z42,NewTransmu,4,TRUE))),"",IF($V42="","",VLOOKUP(Z42,NewTransmu,4,TRUE))) | AB42: =IF(ISERROR(IF(AA42="","",VLOOKUP(AA42,DESCRIPTORS,4,TRUE))),"",IF(AA42="","",VLOOKUP(AA42,DESCRIPTORS,4,TRUE))) | AV42: =(T42/$T$10)*100 -> 0 | AW42: =(U42/$U$10)*100 -> 0 | AX42: =(V42/$V$10)*100 -> 0
A43: 32 | B43: =INPUT!B43 -> 0 | K43: =IF(COUNT($F43:$J43)=0,"",SUM($F43:$J43)) | L43: =IF(ISERROR(IF($K43="","",ROUND(($K43/$K$10)*$L$10,2))),"",IF($K43="","",ROUND(($K43/$K$10)*$L$10,2))) | M43: =IF($L43="","",ROUND($L43*$M$10,2)) | Q43: =IF(COUNT($N43:$P43)=0,"",SUM($N43:$P43)) | R43: =IF(ISERROR(IF($Q43="","",ROUND(($Q43/$Q$10)*$R$10,2))),"",IF($Q43="","",ROUND(($Q43/$Q$10)*$R$10,2))) | S43: =IF($R43="","",ROUND($R43*$S$10,2)) | W43: =IF(COUNT($T43:$V43)=0,"",SUM($T43:$V43)) | X43: =IF(ISERROR(IF($W43="","",ROUND(($W43/$W$10)*$X$10,2))),"",IF($W43="","",ROUND(($W43/$W$10)*$X$10,2))) | Y43: =IF($X43="","",ROUND($X43*$Y$10,2)) | Z43: =IF(ISERROR(IF($V43="","",ROUND(SUM($M43,$S43,$Y43),2))),"",IF($V43="","",ROUND(SUM($M43,$S43,$Y43),2))) | AA43: =IF(ISERROR(IF($V43="","",VLOOKUP(Z43,NewTransmu,4,TRUE))),"",IF($V43="","",VLOOKUP(Z43,NewTransmu,4,TRUE))) | AB43: =IF(ISERROR(IF(AA43="","",VLOOKUP(AA43,DESCRIPTORS,4,TRUE))),"",IF(AA43="","",VLOOKUP(AA43,DESCRIPTORS,4,TRUE))) | AV43: =(T43/$T$10)*100 -> 0 | AW43: =(U43/$U$10)*100 -> 0 | AX43: =(V43/$V$10)*100 -> 0
...

Sheet TERM2
A1: Class Record
B4: REGION | G4: =INPUT!G4 -> 0 | I4: DIVISION | L4: =INPUT!L4 -> 0
B5: SCHOOL NAME | G5: =INPUT!G5 -> 0 | Q5: SCHOOL ID | S5: =INPUT!S5 -> 0 | V5: SCHOOL YEAR | Z5: =INPUT!Y5 -> 0
A7: TERM 2 | F7: GRADE & SECTION: | J7: =INPUT!J7 -> 0 | N7: TEACHER: | Q7: =INPUT!Q7 -> 0 | X7: SUBJECT: | Z7: =INPUT!Y7 -> Science
B8: LEARNERS' NAMES | F8: WRITTEN / ORAL WORKS (20%) | N8: PRODUCT / PERFORMANCE TASKS (50%) | T8: SUMMATIVE TESTS AND TERM EXAMINATIONS (30%) | Z8: Initial Grade | AA8: Term Grade | AB8: Descriptior
F9: 1 | G9: 2 | H9: 3 | I9: 4 | J9: 5 | K9: Total | L9: PS | M9: WS | N9: 1 | O9: 2 | P9: 3 | Q9: Total | R9: PS | S9: WS | T9: ST1 | U9: ST2 | V9: TE | W9: Total | X9: PS | Y9: WS
B10: HIGHEST POSSIBLE SCORE | F10: 15 | G10: 20 | K10: =IF(COUNT($F10:$J10)=0,"",SUM($F10:$J10)) -> 35 | L10: 100 | M10: 0.2 | N10: 50 | O10: 90 | P10: 70 | Q10: =IF(COUNT($N10:$P10)=0,"",SUM($N10:$P10)) -> 210 | R10: 100 | S10: 0.5 | T10: 40 | U10: 40 | V10: 40 | W10: {=IF(COUNT($T10:$V10=0),"",SUM($T10:$V10))} -> 120 | X10: 100 | Y10: 0.3
B11: MALE | AD11: TEST/EXAM RESULT ANALYSIS | AV11: ST1 | AW11: ST2 | AX11: TE
A12: 1 | B12: =INPUT!B12 -> Alvarez, Neitan | F12: 14 | G12: 17 | K12: =IF(COUNT($F12:$J12)=0,"",SUM($F12:$J12)) -> 31 | L12: =IF(ISERROR(IF($K12="","",ROUND(($K12/$K$10)*$L$10,2))),"",IF($K12="","",ROUND(($K12/$K$10)*$L$10,2))) -> 88.57 | M12: =IF($L12="","",ROUND($L12*$M$10,2)) -> 17.71 | N12: 30 | O12: 85 | P12: 63 | Q12: =IF(COUNT($N12:$P12)=0,"",SUM($N12:$P12)) -> 178 | R12: =IF(ISERROR(IF($Q12="","",ROUND(($Q12/$Q$10)*$R$10,2))),"",IF($Q12="","",ROUND(($Q12/$Q$10)*$R$10,2))) -> 84.76 | S12: =IF($R12="","",ROUND($R12*$S$10,2)) -> 42.38 | T12: 26 | U12: 35 | V12: 36 | W12: =IF(COUNT($T12:$V12)=0,"",SUM($T12:$V12)) -> 97 | X12: =IF(ISERROR(IF($W12="","",ROUND(($W12/$W$10)*$X$10,2))),"",IF($W12="","",ROUND(($W12/$W$10)*$X$10,2))) -> 80.83 | Y12: =IF($X12="","",ROUND($X12*$Y$10,2)) -> 24.25 | Z12: =IF(ISERROR(IF($W12="","",ROUND(SUM($M12,$S12,$Y12),2))),"",IF($W12="","",ROUND(SUM($M12,$S12,$Y12),2))) -> 84.34 | AA12: =IF(ISERROR(IF($W12="","",VLOOKUP(Z12,NewTransmu,4,TRUE))),"",IF($W12="","",VLOOKUP(Z12,NewTransmu,4,TRUE))) -> 86 | AB12: =IF(ISERROR(IF(AA12="","",VLOOKUP(AA12,DESCRIPTORS,4,TRUE))),"",IF(AA12="","",VLOOKUP(AA12,DESCRIPTORS,4,TRUE))) -> Benchmarking | AV12: =(T12/$T$10)*100 -> 65 | AW12: =(U12/$U$10)*100 -> 87.5 | AX12: =(V12/$V$10)*100 -> 90
A13: 2 | B13: =INPUT!B13 -> Bautista, Mark | F13: 12 | G13: 16 | K13: =IF(COUNT($F13:$J13)=0,"",SUM($F13:$J13)) -> 28 | L13: =IF(ISERROR(IF($K13="","",ROUND(($K13/$K$10)*$L$10,2))),"",IF($K13="","",ROUND(($K13/$K$10)*$L$10,2))) -> 80 | M13: =IF($L13="","",ROUND($L13*$M$10,2)) -> 16 | N13: 31 | O13: 87 | P13: 65 | Q13: =IF(COUNT($N13:$P13)=0,"",SUM($N13:$P13)) -> 183 | R13: =IF(ISERROR(IF($Q13="","",ROUND(($Q13/$Q$10)*$R$10,2))),"",IF($Q13="","",ROUND(($Q13/$Q$10)*$R$10,2))) -> 87.14 | S13: =IF($R13="","",ROUND($R13*$S$10,2)) -> 43.57 | T13: 31 | U13: 30 | V13: 35 | W13: =IF(COUNT($T13:$V13)=0,"",SUM($T13:$V13)) -> 96 | X13: =IF(ISERROR(IF($W13="","",ROUND(($W13/$W$10)*$X$10,2))),"",IF($W13="","",ROUND(($W13/$W$10)*$X$10,2))) -> 80 | Y13: =IF($X13="","",ROUND($X13*$Y$10,2)) -> 24 | Z13: =IF(ISERROR(IF($V13="","",ROUND(SUM($M13,$S13,$Y13),2))),"",IF($V13="","",ROUND(SUM($M13,$S13,$Y13),2))) -> 83.57 | AA13: =IF(ISERROR(IF($V13="","",VLOOKUP(Z13,NewTransmu,4,TRUE))),"",IF($V13="","",VLOOKUP(Z13,NewTransmu,4,TRUE))) -> 85 | AB13: =IF(ISERROR(IF(AA13="","",VLOOKUP(AA13,DESCRIPTORS,4,TRUE))),"",IF(AA13="","",VLOOKUP(AA13,DESCRIPTORS,4,TRUE))) -> Benchmarking | AE13: ST1 | AF13: ST2 | AG13: TE | AV13: =(T13/$T$10)*100 -> 77.5 | AW13: =(U13/$U$10)*100 -> 75 | AX13: =(V13/$V$10)*100 -> 87.5
A14: 3 | B14: =INPUT!B14 -> Castro, Daniel | F14: 10 | G14: 15 | K14: =IF(COUNT($F14:$J14)=0,"",SUM($F14:$J14)) -> 25 | L14: =IF(ISERROR(IF($K14="","",ROUND(($K14/$K$10)*$L$10,2))),"",IF($K14="","",ROUND(($K14/$K$10)*$L$10,2))) -> 71.43 | M14: =IF($L14="","",ROUND($L14*$M$10,2)) -> 14.29 | N14: 32 | O14: 86 | P14: 60 | Q14: =IF(COUNT($N14:$P14)=0,"",SUM($N14:$P14)) -> 178 | R14: =IF(ISERROR(IF($Q14="","",ROUND(($Q14/$Q$10)*$R$10,2))),"",IF($Q14="","",ROUND(($Q14/$Q$10)*$R$10,2))) -> 84.76 | S14: =IF($R14="","",ROUND($R14*$S$10,2)) -> 42.38 | T14: 30 | U14: 30 | V14: 30 | W14: =IF(COUNT($T14:$V14)=0,"",SUM($T14:$V14)) -> 90 | X14: =IF(ISERROR(IF($W14="","",ROUND(($W14/$W$10)*$X$10,2))),"",IF($W14="","",ROUND(($W14/$W$10)*$X$10,2))) -> 75 | Y14: =IF($X14="","",ROUND($X14*$Y$10,2)) -> 22.5 | Z14: =IF(ISERROR(IF($V14="","",ROUND(SUM($M14,$S14,$Y14),2))),"",IF($V14="","",ROUND(SUM($M14,$S14,$Y14),2))) -> 79.17 | AA14: =IF(ISERROR(IF($V14="","",VLOOKUP(Z14,NewTransmu,4,TRUE))),"",IF($V14="","",VLOOKUP(Z14,NewTransmu,4,TRUE))) -> 81 | AB14: =IF(ISERROR(IF(AA14="","",VLOOKUP(AA14,DESCRIPTORS,4,TRUE))),"",IF(AA14="","",VLOOKUP(AA14,DESCRIPTORS,4,TRUE))) -> Benchmarking | AD14: Number of Examinees: | AE14: =COUNTA(T12:T112) -> 6 | AF14: =COUNTA(U12:U112) -> 6 | AG14: =COUNTA(V12:V112) -> 6 | AV14: =(T14/$T$10)*100 -> 75 | AW14: =(U14/$U$10)*100 -> 75 | AX14: =(V14/$V$10)*100 -> 75
A15: 4 | B15: =INPUT!B15 -> 0 | K15: =IF(COUNT($F15:$J15)=0,"",SUM($F15:$J15)) | L15: =IF(ISERROR(IF($K15="","",ROUND(($K15/$K$10)*$L$10,2))),"",IF($K15="","",ROUND(($K15/$K$10)*$L$10,2))) | M15: =IF($L15="","",ROUND($L15*$M$10,2)) | Q15: =IF(COUNT($N15:$P15)=0,"",SUM($N15:$P15)) | R15: =IF(ISERROR(IF($Q15="","",ROUND(($Q15/$Q$10)*$R$10,2))),"",IF($Q15="","",ROUND(($Q15/$Q$10)*$R$10,2))) | S15: =IF($R15="","",ROUND($R15*$S$10,2)) | W15: =IF(COUNT($T15:$V15)=0,"",SUM($T15:$V15)) | X15: =IF(ISERROR(IF($W15="","",ROUND(($W15/$W$10)*$X$10,2))),"",IF($W15="","",ROUND(($W15/$W$10)*$X$10,2))) | Y15: =IF($X15="","",ROUND($X15*$Y$10,2)) | Z15: =IF(ISERROR(IF($V15="","",ROUND(SUM($M15,$S15,$Y15),2))),"",IF($V15="","",ROUND(SUM($M15,$S15,$Y15),2))) | AA15: =IF(ISERROR(IF($V15="","",VLOOKUP(Z15,NewTransmu,4,TRUE))),"",IF($V15="","",VLOOKUP(Z15,NewTransmu,4,TRUE))) | AB15: =IF(ISERROR(IF(AA15="","",VLOOKUP(AA15,DESCRIPTORS,4,TRUE))),"",IF(AA15="","",VLOOKUP(AA15,DESCRIPTORS,4,TRUE))) | AD15: Highest Possible Score: | AE15: =T10 -> 40 | AF15: =U10 -> 40 | AG15: =V10 -> 40 | AV15: =(T15/$T$10)*100 -> 0 | AW15: =(U15/$U$10)*100 -> 0 | AX15: =(V15/$V$10)*100 -> 0
A16: 5 | B16: =INPUT!B16 -> 0 | K16: =IF(COUNT($F16:$J16)=0,"",SUM($F16:$J16)) | L16: =IF(ISERROR(IF($K16="","",ROUND(($K16/$K$10)*$L$10,2))),"",IF($K16="","",ROUND(($K16/$K$10)*$L$10,2))) | M16: =IF($L16="","",ROUND($L16*$M$10,2)) | Q16: =IF(COUNT($N16:$P16)=0,"",SUM($N16:$P16)) | R16: =IF(ISERROR(IF($Q16="","",ROUND(($Q16/$Q$10)*$R$10,2))),"",IF($Q16="","",ROUND(($Q16/$Q$10)*$R$10,2))) | S16: =IF($R16="","",ROUND($R16*$S$10,2)) | W16: =IF(COUNT($T16:$V16)=0,"",SUM($T16:$V16)) | X16: =IF(ISERROR(IF($W16="","",ROUND(($W16/$W$10)*$X$10,2))),"",IF($W16="","",ROUND(($W16/$W$10)*$X$10,2))) | Y16: =IF($X16="","",ROUND($X16*$Y$10,2)) | Z16: =IF(ISERROR(IF($V16="","",ROUND(SUM($M16,$S16,$Y16),2))),"",IF($V16="","",ROUND(SUM($M16,$S16,$Y16),2))) | AA16: =IF(ISERROR(IF($V16="","",VLOOKUP(Z16,NewTransmu,4,TRUE))),"",IF($V16="","",VLOOKUP(Z16,NewTransmu,4,TRUE))) | AB16: =IF(ISERROR(IF(AA16="","",VLOOKUP(AA16,DESCRIPTORS,4,TRUE))),"",IF(AA16="","",VLOOKUP(AA16,DESCRIPTORS,4,TRUE))) | AV16: =(T16/$T$10)*100 -> 0 | AW16: =(U16/$U$10)*100 -> 0 | AX16: =(V16/$V$10)*100 -> 0
A17: 6 | B17: =INPUT!B17 -> 0 | K17: =IF(COUNT($F17:$J17)=0,"",SUM($F17:$J17)) | L17: =IF(ISERROR(IF($K17="","",ROUND(($K17/$K$10)*$L$10,2))),"",IF($K17="","",ROUND(($K17/$K$10)*$L$10,2))) | M17: =IF($L17="","",ROUND($L17*$M$10,2)) | Q17: =IF(COUNT($N17:$P17)=0,"",SUM($N17:$P17)) | R17: =IF(ISERROR(IF($Q17="","",ROUND(($Q17/$Q$10)*$R$10,2))),"",IF($Q17="","",ROUND(($Q17/$Q$10)*$R$10,2))) | S17: =IF($R17="","",ROUND($R17*$S$10,2)) | W17: =IF(COUNT($T17:$V17)=0,"",SUM($T17:$V17)) | X17: =IF(ISERROR(IF($W17="","",ROUND(($W17/$W$10)*$X$10,2))),"",IF($W17="","",ROUND(($W17/$W$10)*$X$10,2))) | Y17: =IF($X17="","",ROUND($X17*$Y$10,2)) | Z17: =IF(ISERROR(IF($V17="","",ROUND(SUM($M17,$S17,$Y17),2))),"",IF($V17="","",ROUND(SUM($M17,$S17,$Y17),2))) | AA17: =IF(ISERROR(IF($V17="","",VLOOKUP(Z17,NewTransmu,4,TRUE))),"",IF($V17="","",VLOOKUP(Z17,NewTransmu,4,TRUE))) | AB17: =IF(ISERROR(IF(AA17="","",VLOOKUP(AA17,DESCRIPTORS,4,TRUE))),"",IF(AA17="","",VLOOKUP(AA17,DESCRIPTORS,4,TRUE))) | AD17: CRITERION-REFERENCED | AE17: ST1 | AF17: ST2 | AG17: TE | AV17: =(T17/$T$10)*100 -> 0 | AW17: =(U17/$U$10)*100 -> 0 | AX17: =(V17/$V$10)*100 -> 0
A18: 7 | B18: =INPUT!B18 -> 0 | K18: =IF(COUNT($F18:$J18)=0,"",SUM($F18:$J18)) | L18: =IF(ISERROR(IF($K18="","",ROUND(($K18/$K$10)*$L$10,2))),"",IF($K18="","",ROUND(($K18/$K$10)*$L$10,2))) | M18: =IF($L18="","",ROUND($L18*$M$10,2)) | Q18: =IF(COUNT($N18:$P18)=0,"",SUM($N18:$P18)) | R18: =IF(ISERROR(IF($Q18="","",ROUND(($Q18/$Q$10)*$R$10,2))),"",IF($Q18="","",ROUND(($Q18/$Q$10)*$R$10,2))) | S18: =IF($R18="","",ROUND($R18*$S$10,2)) | W18: =IF(COUNT($T18:$V18)=0,"",SUM($T18:$V18)) | X18: =IF(ISERROR(IF($W18="","",ROUND(($W18/$W$10)*$X$10,2))),"",IF($W18="","",ROUND(($W18/$W$10)*$X$10,2))) | Y18: =IF($X18="","",ROUND($X18*$Y$10,2)) | Z18: =IF(ISERROR(IF($V18="","",ROUND(SUM($M18,$S18,$Y18),2))),"",IF($V18="","",ROUND(SUM($M18,$S18,$Y18),2))) | AA18: =IF(ISERROR(IF($V18="","",VLOOKUP(Z18,NewTransmu,4,TRUE))),"",IF($V18="","",VLOOKUP(Z18,NewTransmu,4,TRUE))) | AB18: =IF(ISERROR(IF(AA18="","",VLOOKUP(AA18,DESCRIPTORS,4,TRUE))),"",IF(AA18="","",VLOOKUP(AA18,DESCRIPTORS,4,TRUE))) | AD18: Got 75% & above | AE18: =COUNTIF(AV12:AV112,">=75") -> 4 | AF18: =COUNTIF(AW12:AW112,">=75") -> 6 | AG18: =COUNTIF(AX12:AX112,">=75") -> 6 | AV18: =(T18/$T$10)*100 -> 0 | AW18: =(U18/$U$10)*100 -> 0 | AX18: =(V18/$V$10)*100 -> 0
A19: 8 | B19: =INPUT!B19 -> 0 | K19: =IF(COUNT($F19:$J19)=0,"",SUM($F19:$J19)) | L19: =IF(ISERROR(IF($K19="","",ROUND(($K19/$K$10)*$L$10,2))),"",IF($K19="","",ROUND(($K19/$K$10)*$L$10,2))) | M19: =IF($L19="","",ROUND($L19*$M$10,2)) | Q19: =IF(COUNT($N19:$P19)=0,"",SUM($N19:$P19)) | R19: =IF(ISERROR(IF($Q19="","",ROUND(($Q19/$Q$10)*$R$10,2))),"",IF($Q19="","",ROUND(($Q19/$Q$10)*$R$10,2))) | S19: =IF($R19="","",ROUND($R19*$S$10,2)) | W19: =IF(COUNT($T19:$V19)=0,"",SUM($T19:$V19)) | X19: =IF(ISERROR(IF($W19="","",ROUND(($W19/$W$10)*$X$10,2))),"",IF($W19="","",ROUND(($W19/$W$10)*$X$10,2))) | Y19: =IF($X19="","",ROUND($X19*$Y$10,2)) | Z19: =IF(ISERROR(IF($V19="","",ROUND(SUM($M19,$S19,$Y19),2))),"",IF($V19="","",ROUND(SUM($M19,$S19,$Y19),2))) | AA19: =IF(ISERROR(IF($V19="","",VLOOKUP(Z19,NewTransmu,4,TRUE))),"",IF($V19="","",VLOOKUP(Z19,NewTransmu,4,TRUE))) | AB19: =IF(ISERROR(IF(AA19="","",VLOOKUP(AA19,DESCRIPTORS,4,TRUE))),"",IF(AA19="","",VLOOKUP(AA19,DESCRIPTORS,4,TRUE))) | AD19: Percentage | AE19: =IFERROR(AE18/AE14,"") -> 0.66666667 | AF19: =IFERROR(AF18/AF14,"") -> 1 | AG19: =IFERROR(AG18/AG14,"") -> 1 | AV19: =(T19/$T$10)*100 -> 0 | AW19: =(U19/$U$10)*100 -> 0 | AX19: =(V19/$V$10)*100 -> 0
A20: 9 | B20: =INPUT!B20 -> 0 | K20: =IF(COUNT($F20:$J20)=0,"",SUM($F20:$J20)) | L20: =IF(ISERROR(IF($K20="","",ROUND(($K20/$K$10)*$L$10,2))),"",IF($K20="","",ROUND(($K20/$K$10)*$L$10,2))) | M20: =IF($L20="","",ROUND($L20*$M$10,2)) | Q20: =IF(COUNT($N20:$P20)=0,"",SUM($N20:$P20)) | R20: =IF(ISERROR(IF($Q20="","",ROUND(($Q20/$Q$10)*$R$10,2))),"",IF($Q20="","",ROUND(($Q20/$Q$10)*$R$10,2))) | S20: =IF($R20="","",ROUND($R20*$S$10,2)) | W20: =IF(COUNT($T20:$V20)=0,"",SUM($T20:$V20)) | X20: =IF(ISERROR(IF($W20="","",ROUND(($W20/$W$10)*$X$10,2))),"",IF($W20="","",ROUND(($W20/$W$10)*$X$10,2))) | Y20: =IF($X20="","",ROUND($X20*$Y$10,2)) | Z20: =IF(ISERROR(IF($V20="","",ROUND(SUM($M20,$S20,$Y20),2))),"",IF($V20="","",ROUND(SUM($M20,$S20,$Y20),2))) | AA20: =IF(ISERROR(IF($V20="","",VLOOKUP(Z20,NewTransmu,4,TRUE))),"",IF($V20="","",VLOOKUP(Z20,NewTransmu,4,TRUE))) | AB20: =IF(ISERROR(IF(AA20="","",VLOOKUP(AA20,DESCRIPTORS,4,TRUE))),"",IF(AA20="","",VLOOKUP(AA20,DESCRIPTORS,4,TRUE))) | AD20: Got below 75% | AE20: =AE14-AE18 -> 2 | AF20: =AF14-AF18 -> 0 | AG20: =AG14-AG18 -> 0 | AV20: =(T20/$T$10)*100 -> 0 | AW20: =(U20/$U$10)*100 -> 0 | AX20: =(V20/$V$10)*100 -> 0
A21: 10 | B21: =INPUT!B21 -> 0 | K21: =IF(COUNT($F21:$J21)=0,"",SUM($F21:$J21)) | L21: =IF(ISERROR(IF($K21="","",ROUND(($K21/$K$10)*$L$10,2))),"",IF($K21="","",ROUND(($K21/$K$10)*$L$10,2))) | M21: =IF($L21="","",ROUND($L21*$M$10,2)) | Q21: =IF(COUNT($N21:$P21)=0,"",SUM($N21:$P21)) | R21: =IF(ISERROR(IF($Q21="","",ROUND(($Q21/$Q$10)*$R$10,2))),"",IF($Q21="","",ROUND(($Q21/$Q$10)*$R$10,2))) | S21: =IF($R21="","",ROUND($R21*$S$10,2)) | W21: =IF(COUNT($T21:$V21)=0,"",SUM($T21:$V21)) | X21: =IF(ISERROR(IF($W21="","",ROUND(($W21/$W$10)*$X$10,2))),"",IF($W21="","",ROUND(($W21/$W$10)*$X$10,2))) | Y21: =IF($X21="","",ROUND($X21*$Y$10,2)) | Z21: =IF(ISERROR(IF($V21="","",ROUND(SUM($M21,$S21,$Y21),2))),"",IF($V21="","",ROUND(SUM($M21,$S21,$Y21),2))) | AA21: =IF(ISERROR(IF($V21="","",VLOOKUP(Z21,NewTransmu,4,TRUE))),"",IF($V21="","",VLOOKUP(Z21,NewTransmu,4,TRUE))) | AB21: =IF(ISERROR(IF(AA21="","",VLOOKUP(AA21,DESCRIPTORS,4,TRUE))),"",IF(AA21="","",VLOOKUP(AA21,DESCRIPTORS,4,TRUE))) | AD21: Percentage | AE21: =IFERROR(1-AE19,"") -> 0.33333333 | AF21: =IFERROR(1-AF19,"") -> 0 | AG21: =IFERROR(1-AG19,"") -> 0 | AV21: =(T21/$T$10)*100 -> 0 | AW21: =(U21/$U$10)*100 -> 0 | AX21: =(V21/$V$10)*100 -> 0
A22: 11 | B22: =INPUT!B22 -> 0 | K22: =IF(COUNT($F22:$J22)=0,"",SUM($F22:$J22)) | L22: =IF(ISERROR(IF($K22="","",ROUND(($K22/$K$10)*$L$10,2))),"",IF($K22="","",ROUND(($K22/$K$10)*$L$10,2))) | M22: =IF($L22="","",ROUND($L22*$M$10,2)) | Q22: =IF(COUNT($N22:$P22)=0,"",SUM($N22:$P22)) | R22: =IF(ISERROR(IF($Q22="","",ROUND(($Q22/$Q$10)*$R$10,2))),"",IF($Q22="","",ROUND(($Q22/$Q$10)*$R$10,2))) | S22: =IF($R22="","",ROUND($R22*$S$10,2)) | W22: =IF(COUNT($T22:$V22)=0,"",SUM($T22:$V22)) | X22: =IF(ISERROR(IF($W22="","",ROUND(($W22/$W$10)*$X$10,2))),"",IF($W22="","",ROUND(($W22/$W$10)*$X$10,2))) | Y22: =IF($X22="","",ROUND($X22*$Y$10,2)) | Z22: =IF(ISERROR(IF($V22="","",ROUND(SUM($M22,$S22,$Y22),2))),"",IF($V22="","",ROUND(SUM($M22,$S22,$Y22),2))) | AA22: =IF(ISERROR(IF($V22="","",VLOOKUP(Z22,NewTransmu,4,TRUE))),"",IF($V22="","",VLOOKUP(Z22,NewTransmu,4,TRUE))) | AB22: =IF(ISERROR(IF(AA22="","",VLOOKUP(AA22,DESCRIPTORS,4,TRUE))),"",IF(AA22="","",VLOOKUP(AA22,DESCRIPTORS,4,TRUE))) | AV22: =(T22/$T$10)*100 -> 0 | AW22: =(U22/$U$10)*100 -> 0 | AX22: =(V22/$V$10)*100 -> 0
A23: 12 | B23: =INPUT!B23 -> 0 | K23: =IF(COUNT($F23:$J23)=0,"",SUM($F23:$J23)) | L23: =IF(ISERROR(IF($K23="","",ROUND(($K23/$K$10)*$L$10,2))),"",IF($K23="","",ROUND(($K23/$K$10)*$L$10,2))) | M23: =IF($L23="","",ROUND($L23*$M$10,2)) | Q23: =IF(COUNT($N23:$P23)=0,"",SUM($N23:$P23)) | R23: =IF(ISERROR(IF($Q23="","",ROUND(($Q23/$Q$10)*$R$10,2))),"",IF($Q23="","",ROUND(($Q23/$Q$10)*$R$10,2))) | S23: =IF($R23="","",ROUND($R23*$S$10,2)) | W23: =IF(COUNT($T23:$V23)=0,"",SUM($T23:$V23)) | X23: =IF(ISERROR(IF($W23="","",ROUND(($W23/$W$10)*$X$10,2))),"",IF($W23="","",ROUND(($W23/$W$10)*$X$10,2))) | Y23: =IF($X23="","",ROUND($X23*$Y$10,2)) | Z23: =IF(ISERROR(IF($V23="","",ROUND(SUM($M23,$S23,$Y23),2))),"",IF($V23="","",ROUND(SUM($M23,$S23,$Y23),2))) | AA23: =IF(ISERROR(IF($V23="","",VLOOKUP(Z23,NewTransmu,4,TRUE))),"",IF($V23="","",VLOOKUP(Z23,NewTransmu,4,TRUE))) | AB23: =IF(ISERROR(IF(AA23="","",VLOOKUP(AA23,DESCRIPTORS,4,TRUE))),"",IF(AA23="","",VLOOKUP(AA23,DESCRIPTORS,4,TRUE))) | AD23: NORM-REFERENCED | AE23: ST1 | AF23: ST2 | AG23: TE | AV23: =(T23/$T$10)*100 -> 0 | AW23: =(U23/$U$10)*100 -> 0 | AX23: =(V23/$V$10)*100 -> 0
A24: 13 | B24: =INPUT!B24 -> 0 | K24: =IF(COUNT($F24:$J24)=0,"",SUM($F24:$J24)) | L24: =IF(ISERROR(IF($K24="","",ROUND(($K24/$K$10)*$L$10,2))),"",IF($K24="","",ROUND(($K24/$K$10)*$L$10,2))) | M24: =IF($L24="","",ROUND($L24*$M$10,2)) | Q24: =IF(COUNT($N24:$P24)=0,"",SUM($N24:$P24)) | R24: =IF(ISERROR(IF($Q24="","",ROUND(($Q24/$Q$10)*$R$10,2))),"",IF($Q24="","",ROUND(($Q24/$Q$10)*$R$10,2))) | S24: =IF($R24="","",ROUND($R24*$S$10,2)) | W24: =IF(COUNT($T24:$V24)=0,"",SUM($T24:$V24)) | X24: =IF(ISERROR(IF($W24="","",ROUND(($W24/$W$10)*$X$10,2))),"",IF($W24="","",ROUND(($W24/$W$10)*$X$10,2))) | Y24: =IF($X24="","",ROUND($X24*$Y$10,2)) | Z24: =IF(ISERROR(IF($V24="","",ROUND(SUM($M24,$S24,$Y24),2))),"",IF($V24="","",ROUND(SUM($M24,$S24,$Y24),2))) | AA24: =IF(ISERROR(IF($V24="","",VLOOKUP(Z24,NewTransmu,4,TRUE))),"",IF($V24="","",VLOOKUP(Z24,NewTransmu,4,TRUE))) | AB24: =IF(ISERROR(IF(AA24="","",VLOOKUP(AA24,DESCRIPTORS,4,TRUE))),"",IF(AA24="","",VLOOKUP(AA24,DESCRIPTORS,4,TRUE))) | AD24: Mean | AE24: =IFERROR(AVERAGE(T12:T112),"") -> 29 | AF24: =IFERROR(AVERAGE(U12:U112),"") -> 31.666667 | AG24: =IFERROR(AVERAGE(V12:V112),"") -> 33.666667 | AV24: =(T24/$T$10)*100 -> 0 | AW24: =(U24/$U$10)*100 -> 0 | AX24: =(V24/$V$10)*100 -> 0
A25: 14 | B25: =INPUT!B25 -> 0 | K25: =IF(COUNT($F25:$J25)=0,"",SUM($F25:$J25)) | L25: =IF(ISERROR(IF($K25="","",ROUND(($K25/$K$10)*$L$10,2))),"",IF($K25="","",ROUND(($K25/$K$10)*$L$10,2))) | M25: =IF($L25="","",ROUND($L25*$M$10,2)) | Q25: =IF(COUNT($N25:$P25)=0,"",SUM($N25:$P25)) | R25: =IF(ISERROR(IF($Q25="","",ROUND(($Q25/$Q$10)*$R$10,2))),"",IF($Q25="","",ROUND(($Q25/$Q$10)*$R$10,2))) | S25: =IF($R25="","",ROUND($R25*$S$10,2)) | W25: =IF(COUNT($T25:$V25)=0,"",SUM($T25:$V25)) | X25: =IF(ISERROR(IF($W25="","",ROUND(($W25/$W$10)*$X$10,2))),"",IF($W25="","",ROUND(($W25/$W$10)*$X$10,2))) | Y25: =IF($X25="","",ROUND($X25*$Y$10,2)) | Z25: =IF(ISERROR(IF($V25="","",ROUND(SUM($M25,$S25,$Y25),2))),"",IF($V25="","",ROUND(SUM($M25,$S25,$Y25),2))) | AA25: =IF(ISERROR(IF($V25="","",VLOOKUP(Z25,NewTransmu,4,TRUE))),"",IF($V25="","",VLOOKUP(Z25,NewTransmu,4,TRUE))) | AB25: =IF(ISERROR(IF(AA25="","",VLOOKUP(AA25,DESCRIPTORS,4,TRUE))),"",IF(AA25="","",VLOOKUP(AA25,DESCRIPTORS,4,TRUE))) | AD25: Median | AE25: =IFERROR(MEDIAN(T12:T112),"") -> 30 | AF25: =IFERROR(MEDIAN(U12:U112),"") -> 30 | AG25: =IFERROR(MEDIAN(V12:V112),"") -> 35 | AV25: =(T25/$T$10)*100 -> 0 | AW25: =(U25/$U$10)*100 -> 0 | AX25: =(V25/$V$10)*100 -> 0
A26: 15 | B26: =INPUT!B26 -> 0 | K26: =IF(COUNT($F26:$J26)=0,"",SUM($F26:$J26)) | L26: =IF(ISERROR(IF($K26="","",ROUND(($K26/$K$10)*$L$10,2))),"",IF($K26="","",ROUND(($K26/$K$10)*$L$10,2))) | M26: =IF($L26="","",ROUND($L26*$M$10,2)) | Q26: =IF(COUNT($N26:$P26)=0,"",SUM($N26:$P26)) | R26: =IF(ISERROR(IF($Q26="","",ROUND(($Q26/$Q$10)*$R$10,2))),"",IF($Q26="","",ROUND(($Q26/$Q$10)*$R$10,2))) | S26: =IF($R26="","",ROUND($R26*$S$10,2)) | W26: =IF(COUNT($T26:$V26)=0,"",SUM($T26:$V26)) | X26: =IF(ISERROR(IF($W26="","",ROUND(($W26/$W$10)*$X$10,2))),"",IF($W26="","",ROUND(($W26/$W$10)*$X$10,2))) | Y26: =IF($X26="","",ROUND($X26*$Y$10,2)) | Z26: =IF(ISERROR(IF($V26="","",ROUND(SUM($M26,$S26,$Y26),2))),"",IF($V26="","",ROUND(SUM($M26,$S26,$Y26),2))) | AA26: =IF(ISERROR(IF($V26="","",VLOOKUP(Z26,NewTransmu,4,TRUE))),"",IF($V26="","",VLOOKUP(Z26,NewTransmu,4,TRUE))) | AB26: =IF(ISERROR(IF(AA26="","",VLOOKUP(AA26,DESCRIPTORS,4,TRUE))),"",IF(AA26="","",VLOOKUP(AA26,DESCRIPTORS,4,TRUE))) | AD26: SD | AE26: =IFERROR(_xlfn.STDEV.S(T12:T112),"") -> 2.3664319 | AF26: =_xlfn.STDEV.S(U12:U112) -> 2.5819889 | AG26: =_xlfn.STDEV.S(V12:V112) -> 2.8751812 | AV26: =(T26/$T$10)*100 -> 0 | AW26: =(U26/$U$10)*100 -> 0 | AX26: =(V26/$V$10)*100 -> 0
